{"sample_number":1,"sample_utc":"2026-06-18T18:00:04.8463905+00:00","asset":"BTC","market_slug":"btc-updown-5m-1781805300","outcome":"Up","token_id":"100366993284555439229136263731142874057115468471011666953870421192847222766172","book":{"market":"0xa29dcb1f54b9d4e75465fcab657a4928c3952dad4b4828bcd9944e11f2b1d070","asset_id":"100366993284555439229136263731142874057115468471011666953870421192847222766172","timestamp":"1781805605186","hash":"4761e6ee731c783e58ec95b5fb81eb979cdeccf6","bids":[],"asks":[{"price":"0.99","size":"113302"},{"price":"0.98","size":"4248.57"},{"price":"0.97","size":"67"},{"price":"0.96","size":"26941.75"},{"price":"0.95","size":"30131"},{"price":"0.94","size":"8066"},{"price":"0.93","size":"1366"},{"price":"0.92","size":"1064"},{"price":"0.91","size":"3034"},{"price":"0.9","size":"3072"},{"price":"0.89","size":"2629"},{"price":"0.88","size":"7018"},{"price":"0.87","size":"5"},{"price":"0.86","size":"2605"},{"price":"0.85","size":"5"},{"price":"0.84","size":"5"},{"price":"0.83","size":"29"},{"price":"0.82","size":"3004"},{"price":"0.81","size":"3004"},{"price":"0.8","size":"692"},{"price":"0.79","size":"3004"},{"price":"0.78","size":"5"},{"price":"0.77","size":"5"},{"price":"0.76","size":"3004"},{"price":"0.75","size":"5"},{"price":"0.74","size":"2004"},{"price":"0.73","size":"2004"},{"price":"0.72","size":"5"},{"price":"0.71","size":"5"},{"price":"0.7","size":"646"},{"price":"0.69","size":"3004"},{"price":"0.68","size":"5"},{"price":"0.67","size":"5"},{"price":"0.66","size":"2004"},{"price":"0.65","size":"2004"},{"price":"0.64","size":"5"},{"price":"0.63","size":"5"},{"price":"0.62","size":"5"},{"price":"0.61","size":"5"},{"price":"0.6","size":"31"},{"price":"0.59","size":"5"},{"price":"0.58","size":"2605"},{"price":"0.57","size":"2605"},{"price":"0.56","size":"5"},{"price":"0.55","size":"230.69"},{"price":"0.52","size":"20"},{"price":"0.51","size":"28.99"},{"price":"0.5","size":"127"},{"price":"0.49","size":"2005"},{"price":"0.47","size":"1999"},{"price":"0.45","size":"2081"},{"price":"0.43","size":"1999"},{"price":"0.39","size":"1999"},{"price":"0.38","size":"5"},{"price":"0.37","size":"5"},{"price":"0.35","size":"2045"},{"price":"0.33","size":"5"},{"price":"0.32","size":"1999"},{"price":"0.29","size":"2600"},{"price":"0.28","size":"10"},{"price":"0.27","size":"2605"},{"price":"0.25","size":"1600"},{"price":"0.23","size":"1999"},{"price":"0.21","size":"1999"},{"price":"0.2","size":"5"},{"price":"0.16","size":"2059"},{"price":"0.15","size":"23.97"},{"price":"0.12","size":"6.25"},{"price":"0.11","size":"1999"},{"price":"0.09","size":"1999"},{"price":"0.08","size":"1999"},{"price":"0.07","size":"1605"},{"price":"0.05","size":"2015"},{"price":"0.04","size":"2000"},{"price":"0.03","size":"15.05"},{"price":"0.02","size":"1666"},{"price":"0.01","size":"900294.43"}],"min_order_size":"5","tick_size":"0.01","neg_risk":false,"last_trade_price":"0.990"}}
{"sample_number":1,"sample_utc":"2026-06-18T18:00:04.8463905+00:00","asset":"BTC","market_slug":"btc-updown-5m-1781805300","outcome":"Down","token_id":"30945358799682125975622752445436537816479585992099959750063279707586060979279","book":{"market":"0xa29dcb1f54b9d4e75465fcab657a4928c3952dad4b4828bcd9944e11f2b1d070","asset_id":"30945358799682125975622752445436537816479585992099959750063279707586060979279","timestamp":"1781805605969","hash":"ee59ef63981df2e6e0e62ecf9931281295dcd109","bids":[{"price":"0.01","size":"113272"},{"price":"0.02","size":"4218.57"},{"price":"0.03","size":"37"},{"price":"0.04","size":"26911.75"},{"price":"0.05","size":"30101"},{"price":"0.06","size":"8036"},{"price":"0.07","size":"1336"},{"price":"0.08","size":"1034"},{"price":"0.09","size":"3004"},{"price":"0.1","size":"3042"},{"price":"0.11","size":"2629"},{"price":"0.12","size":"7018"},{"price":"0.13","size":"5"},{"price":"0.14","size":"2605"},{"price":"0.15","size":"5"},{"price":"0.16","size":"5"},{"price":"0.17","size":"29"},{"price":"0.18","size":"3004"},{"price":"0.19","size":"3004"},{"price":"0.2","size":"692"},{"price":"0.21","size":"3004"},{"price":"0.22","size":"5"},{"price":"0.23","size":"5"},{"price":"0.24","size":"3004"},{"price":"0.25","size":"5"},{"price":"0.26","size":"2004"},{"price":"0.27","size":"2004"},{"price":"0.28","size":"5"},{"price":"0.29","size":"5"},{"price":"0.3","size":"646"},{"price":"0.31","size":"3004"},{"price":"0.32","size":"5"},{"price":"0.33","size":"5"},{"price":"0.34","size":"2004"},{"price":"0.35","size":"2004"},{"price":"0.36","size":"5"},{"price":"0.37","size":"5"},{"price":"0.38","size":"5"},{"price":"0.39","size":"5"},{"price":"0.4","size":"31"},{"price":"0.41","size":"5"},{"price":"0.42","size":"2605"},{"price":"0.43","size":"2605"},{"price":"0.44","size":"5"},{"price":"0.45","size":"230.69"},{"price":"0.48","size":"20"},{"price":"0.49","size":"28.99"},{"price":"0.5","size":"127"},{"price":"0.51","size":"2005"},{"price":"0.53","size":"1999"},{"price":"0.55","size":"2081"},{"price":"0.57","size":"1999"},{"price":"0.61","size":"1999"},{"price":"0.62","size":"5"},{"price":"0.63","size":"5"},{"price":"0.65","size":"2045"},{"price":"0.67","size":"5"},{"price":"0.68","size":"1999"},{"price":"0.71","size":"2600"},{"price":"0.72","size":"10"},{"price":"0.73","size":"2605"},{"price":"0.75","size":"1600"},{"price":"0.77","size":"1999"},{"price":"0.79","size":"1999"},{"price":"0.8","size":"5"},{"price":"0.84","size":"2059"},{"price":"0.85","size":"23.97"},{"price":"0.88","size":"6.25"},{"price":"0.89","size":"1999"},{"price":"0.91","size":"1999"},{"price":"0.92","size":"1999"},{"price":"0.93","size":"1605"},{"price":"0.95","size":"2015"},{"price":"0.96","size":"2000"},{"price":"0.97","size":"15.05"},{"price":"0.98","size":"1666"},{"price":"0.99","size":"900277.83"}],"asks":[],"min_order_size":"5","tick_size":"0.01","neg_risk":false,"last_trade_price":"0.990"}}
{"sample_number":1,"sample_utc":"2026-06-18T18:00:04.8463905+00:00","asset":"ETH","market_slug":"eth-updown-5m-1781805300","outcome":"Up","token_id":"84464230807213236425016885238522598164473602253759355671732117397567158540848","book":{"market":"0x87d522cbec7d7e644ec5485f60d464a56e7495b8797d51a2e9bb26d96d7c7f93","asset_id":"84464230807213236425016885238522598164473602253759355671732117397567158540848","timestamp":"1781805605289","hash":"ac122058ee3a3117920f37cdf1fbc57163376934","bids":[],"asks":[{"price":"0.99","size":"110800"},{"price":"0.98","size":"1744"},{"price":"0.97","size":"27"},{"price":"0.96","size":"26320"},{"price":"0.95","size":"16"},{"price":"0.94","size":"8000"},{"price":"0.93","size":"960"},{"price":"0.91","size":"999"},{"price":"0.9","size":"999"},{"price":"0.89","size":"2600"},{"price":"0.86","size":"2600"},{"price":"0.82","size":"999"},{"price":"0.81","size":"999"},{"price":"0.8","size":"500"},{"price":"0.74","size":"999"},{"price":"0.73","size":"999"},{"price":"0.7","size":"240"},{"price":"0.66","size":"999"},{"price":"0.65","size":"999"},{"price":"0.58","size":"2600"},{"price":"0.57","size":"2600"},{"price":"0.55","size":"160"},{"price":"0.46","size":"15"},{"price":"0.45","size":"1074"},{"price":"0.43","size":"999"},{"price":"0.35","size":"1029"},{"price":"0.3","size":"5"},{"price":"0.29","size":"2600"},{"price":"0.27","size":"2600"},{"price":"0.26","size":"17.25"},{"price":"0.23","size":"999"},{"price":"0.21","size":"999"},{"price":"0.17","size":"10"},{"price":"0.16","size":"999"},{"price":"0.09","size":"1999"},{"price":"0.08","size":"1999"},{"price":"0.05","size":"2010.26"},{"price":"0.04","size":"2010"},{"price":"0.03","size":"5"},{"price":"0.02","size":"73.59"},{"price":"0.01","size":"567387.5"}],"min_order_size":"5","tick_size":"0.01","neg_risk":false,"last_trade_price":"0.990"}}
{"sample_number":1,"sample_utc":"2026-06-18T18:00:04.8463905+00:00","asset":"ETH","market_slug":"eth-updown-5m-1781805300","outcome":"Down","token_id":"36868621506353927085332735174569787095878720872195622300005980530115725386975","book":{"market":"0x87d522cbec7d7e644ec5485f60d464a56e7495b8797d51a2e9bb26d96d7c7f93","asset_id":"36868621506353927085332735174569787095878720872195622300005980530115725386975","timestamp":"1781805605289","hash":"c72f6ce6fb70d6441666f09e0dd38e375d48546a","bids":[{"price":"0.01","size":"110800"},{"price":"0.02","size":"1744"},{"price":"0.03","size":"27"},{"price":"0.04","size":"26320"},{"price":"0.05","size":"16"},{"price":"0.06","size":"8000"},{"price":"0.07","size":"960"},{"price":"0.09","size":"999"},{"price":"0.1","size":"999"},{"price":"0.11","size":"2600"},{"price":"0.14","size":"2600"},{"price":"0.18","size":"999"},{"price":"0.19","size":"999"},{"price":"0.2","size":"500"},{"price":"0.26","size":"999"},{"price":"0.27","size":"999"},{"price":"0.3","size":"240"},{"price":"0.34","size":"999"},{"price":"0.35","size":"999"},{"price":"0.42","size":"2600"},{"price":"0.43","size":"2600"},{"price":"0.45","size":"160"},{"price":"0.54","size":"15"},{"price":"0.55","size":"1074"},{"price":"0.57","size":"999"},{"price":"0.65","size":"1029"},{"price":"0.7","size":"5"},{"price":"0.71","size":"2600"},{"price":"0.73","size":"2600"},{"price":"0.74","size":"17.25"},{"price":"0.77","size":"999"},{"price":"0.79","size":"999"},{"price":"0.83","size":"10"},{"price":"0.84","size":"999"},{"price":"0.91","size":"1999"},{"price":"0.92","size":"1999"},{"price":"0.95","size":"2010.26"},{"price":"0.96","size":"2010"},{"price":"0.97","size":"5"},{"price":"0.98","size":"73.59"},{"price":"0.99","size":"567387.5"}],"asks":[],"min_order_size":"5","tick_size":"0.01","neg_risk":false,"last_trade_price":"0.990"}}
{"sample_number":1,"sample_utc":"2026-06-18T18:00:04.8463905+00:00","asset":"SOL","market_slug":"sol-updown-5m-1781805300","outcome":"Up","token_id":"43590587833960170489458633973229110190958133890499213708362021339678110080916","book":{"market":"0xa2a7fbb7f3fed9031df9d75228fbf4bfddbc4e8cc4f1fb9015ee7afa5a8bfcef","asset_id":"43590587833960170489458633973229110190958133890499213708362021339678110080916","timestamp":"1781805602307","hash":"f1a30fbc2f087297cd5eb643e336da87b36a0534","bids":[],"asks":[{"price":"0.99","size":"110434"},{"price":"0.98","size":"1389"},{"price":"0.97","size":"27"},{"price":"0.96","size":"25670"},{"price":"0.95","size":"16"},{"price":"0.94","size":"8000"},{"price":"0.93","size":"480"},{"price":"0.91","size":"999"},{"price":"0.9","size":"999"},{"price":"0.89","size":"2600"},{"price":"0.86","size":"2600"},{"price":"0.82","size":"999"},{"price":"0.81","size":"999"},{"price":"0.8","size":"250"},{"price":"0.74","size":"999"},{"price":"0.73","size":"999"},{"price":"0.7","size":"120"},{"price":"0.66","size":"999"},{"price":"0.65","size":"999"},{"price":"0.58","size":"2600"},{"price":"0.57","size":"2600"},{"price":"0.55","size":"80"},{"price":"0.45","size":"1029"},{"price":"0.43","size":"999"},{"price":"0.35","size":"1014"},{"price":"0.29","size":"2600"},{"price":"0.27","size":"2600"},{"price":"0.23","size":"999"},{"price":"0.21","size":"999"},{"price":"0.16","size":"999"},{"price":"0.09","size":"1999"},{"price":"0.08","size":"1999"},{"price":"0.05","size":"2005"},{"price":"0.04","size":"2000"},{"price":"0.02","size":"112"},{"price":"0.01","size":"470291.09"}],"min_order_size":"5","tick_size":"0.01","neg_risk":false,"last_trade_price":"0.990"}}
{"sample_number":1,"sample_utc":"2026-06-18T18:00:04.8463905+00:00","asset":"SOL","market_slug":"sol-updown-5m-1781805300","outcome":"Down","token_id":"64729861947531231910320495939117410106727761033132301855694367299130238199956","book":{"market":"0xa2a7fbb7f3fed9031df9d75228fbf4bfddbc4e8cc4f1fb9015ee7afa5a8bfcef","asset_id":"64729861947531231910320495939117410106727761033132301855694367299130238199956","timestamp":"1781805602307","hash":"4ad229fedb65ccd41365b1189f1fb140daa13c82","bids":[{"price":"0.01","size":"110434"},{"price":"0.02","size":"1389"},{"price":"0.03","size":"27"},{"price":"0.04","size":"25670"},{"price":"0.05","size":"16"},{"price":"0.06","size":"8000"},{"price":"0.07","size":"480"},{"price":"0.09","size":"999"},{"price":"0.1","size":"999"},{"price":"0.11","size":"2600"},{"price":"0.14","size":"2600"},{"price":"0.18","size":"999"},{"price":"0.19","size":"999"},{"price":"0.2","size":"250"},{"price":"0.26","size":"999"},{"price":"0.27","size":"999"},{"price":"0.3","size":"120"},{"price":"0.34","size":"999"},{"price":"0.35","size":"999"},{"price":"0.42","size":"2600"},{"price":"0.43","size":"2600"},{"price":"0.45","size":"80"},{"price":"0.55","size":"1029"},{"price":"0.57","size":"999"},{"price":"0.65","size":"1014"},{"price":"0.71","size":"2600"},{"price":"0.73","size":"2600"},{"price":"0.77","size":"999"},{"price":"0.79","size":"999"},{"price":"0.84","size":"999"},{"price":"0.91","size":"1999"},{"price":"0.92","size":"1999"},{"price":"0.95","size":"2005"},{"price":"0.96","size":"2000"},{"price":"0.98","size":"112"},{"price":"0.99","size":"470291.09"}],"asks":[],"min_order_size":"5","tick_size":"0.01","neg_risk":false,"last_trade_price":"0.990"}}
{"sample_number":2,"sample_utc":"2026-06-18T18:00:38.6342190+00:00","asset":"BTC","market_slug":"btc-updown-5m-1781805300","outcome":"Up","token_id":"100366993284555439229136263731142874057115468471011666953870421192847222766172","book":{"market":"0xa29dcb1f54b9d4e75465fcab657a4928c3952dad4b4828bcd9944e11f2b1d070","asset_id":"100366993284555439229136263731142874057115468471011666953870421192847222766172","timestamp":"1781805635557","hash":"f735d8cbbb02fd2cd87dce464c0f9ce167ff60ef","bids":[],"asks":[{"price":"0.99","size":"112849.7"},{"price":"0.98","size":"4218.57"},{"price":"0.97","size":"37"},{"price":"0.96","size":"26911.75"},{"price":"0.95","size":"30101"},{"price":"0.94","size":"8036"},{"price":"0.93","size":"1336"},{"price":"0.92","size":"1034"},{"price":"0.91","size":"3004"},{"price":"0.9","size":"3042"},{"price":"0.89","size":"2629"},{"price":"0.88","size":"7018"},{"price":"0.87","size":"5"},{"price":"0.86","size":"2605"},{"price":"0.85","size":"5"},{"price":"0.84","size":"5"},{"price":"0.83","size":"29"},{"price":"0.82","size":"3004"},{"price":"0.81","size":"3004"},{"price":"0.8","size":"692"},{"price":"0.79","size":"3004"},{"price":"0.78","size":"5"},{"price":"0.77","size":"5"},{"price":"0.76","size":"3004"},{"price":"0.75","size":"5"},{"price":"0.74","size":"2004"},{"price":"0.73","size":"2004"},{"price":"0.72","size":"5"},{"price":"0.71","size":"5"},{"price":"0.7","size":"646"},{"price":"0.69","size":"3004"},{"price":"0.68","size":"5"},{"price":"0.67","size":"5"},{"price":"0.66","size":"2004"},{"price":"0.65","size":"2004"},{"price":"0.64","size":"5"},{"price":"0.63","size":"5"},{"price":"0.62","size":"5"},{"price":"0.61","size":"5"},{"price":"0.6","size":"31"},{"price":"0.59","size":"5"},{"price":"0.58","size":"2605"},{"price":"0.57","size":"2605"},{"price":"0.56","size":"5"},{"price":"0.55","size":"225"},{"price":"0.52","size":"20"},{"price":"0.51","size":"28.99"},{"price":"0.5","size":"127"},{"price":"0.49","size":"2005"},{"price":"0.47","size":"1999"},{"price":"0.45","size":"2081"},{"price":"0.43","size":"1999"},{"price":"0.39","size":"1999"},{"price":"0.38","size":"5"},{"price":"0.37","size":"5"},{"price":"0.35","size":"2045"},{"price":"0.32","size":"1999"},{"price":"0.29","size":"2600"},{"price":"0.28","size":"5"},{"price":"0.27","size":"2605"},{"price":"0.25","size":"1634.1"},{"price":"0.23","size":"1999"},{"price":"0.21","size":"1999"},{"price":"0.16","size":"2059"},{"price":"0.15","size":"23.97"},{"price":"0.11","size":"1999"},{"price":"0.09","size":"1999"},{"price":"0.08","size":"1999"},{"price":"0.07","size":"1605"},{"price":"0.05","size":"2015"},{"price":"0.04","size":"2000"},{"price":"0.03","size":"15.05"},{"price":"0.02","size":"1650"},{"price":"0.01","size":"896004.67"}],"min_order_size":"5","tick_size":"0.01","neg_risk":false,"last_trade_price":"0.990"}}
{"sample_number":2,"sample_utc":"2026-06-18T18:00:38.6342190+00:00","asset":"BTC","market_slug":"btc-updown-5m-1781805300","outcome":"Down","token_id":"30945358799682125975622752445436537816479585992099959750063279707586060979279","book":{"market":"0xa29dcb1f54b9d4e75465fcab657a4928c3952dad4b4828bcd9944e11f2b1d070","asset_id":"30945358799682125975622752445436537816479585992099959750063279707586060979279","timestamp":"1781805635557","hash":"85c70ff646fc2fb73880a7c3c9eafd978e275f9a","bids":[{"price":"0.01","size":"112849.7"},{"price":"0.02","size":"4218.57"},{"price":"0.03","size":"37"},{"price":"0.04","size":"26911.75"},{"price":"0.05","size":"30101"},{"price":"0.06","size":"8036"},{"price":"0.07","size":"1336"},{"price":"0.08","size":"1034"},{"price":"0.09","size":"3004"},{"price":"0.1","size":"3042"},{"price":"0.11","size":"2629"},{"price":"0.12","size":"7018"},{"price":"0.13","size":"5"},{"price":"0.14","size":"2605"},{"price":"0.15","size":"5"},{"price":"0.16","size":"5"},{"price":"0.17","size":"29"},{"price":"0.18","size":"3004"},{"price":"0.19","size":"3004"},{"price":"0.2","size":"692"},{"price":"0.21","size":"3004"},{"price":"0.22","size":"5"},{"price":"0.23","size":"5"},{"price":"0.24","size":"3004"},{"price":"0.25","size":"5"},{"price":"0.26","size":"2004"},{"price":"0.27","size":"2004"},{"price":"0.28","size":"5"},{"price":"0.29","size":"5"},{"price":"0.3","size":"646"},{"price":"0.31","size":"3004"},{"price":"0.32","size":"5"},{"price":"0.33","size":"5"},{"price":"0.34","size":"2004"},{"price":"0.35","size":"2004"},{"price":"0.36","size":"5"},{"price":"0.37","size":"5"},{"price":"0.38","size":"5"},{"price":"0.39","size":"5"},{"price":"0.4","size":"31"},{"price":"0.41","size":"5"},{"price":"0.42","size":"2605"},{"price":"0.43","size":"2605"},{"price":"0.44","size":"5"},{"price":"0.45","size":"225"},{"price":"0.48","size":"20"},{"price":"0.49","size":"28.99"},{"price":"0.5","size":"127"},{"price":"0.51","size":"2005"},{"price":"0.53","size":"1999"},{"price":"0.55","size":"2081"},{"price":"0.57","size":"1999"},{"price":"0.61","size":"1999"},{"price":"0.62","size":"5"},{"price":"0.63","size":"5"},{"price":"0.65","size":"2045"},{"price":"0.68","size":"1999"},{"price":"0.71","size":"2600"},{"price":"0.72","size":"5"},{"price":"0.73","size":"2605"},{"price":"0.75","size":"1634.1"},{"price":"0.77","size":"1999"},{"price":"0.79","size":"1999"},{"price":"0.84","size":"2059"},{"price":"0.85","size":"23.97"},{"price":"0.89","size":"1999"},{"price":"0.91","size":"1999"},{"price":"0.92","size":"1999"},{"price":"0.93","size":"1605"},{"price":"0.95","size":"2015"},{"price":"0.96","size":"2000"},{"price":"0.97","size":"15.05"},{"price":"0.98","size":"1650"},{"price":"0.99","size":"896004.67"}],"asks":[],"min_order_size":"5","tick_size":"0.01","neg_risk":false,"last_trade_price":"0.990"}}
{"sample_number":2,"sample_utc":"2026-06-18T18:00:38.6342190+00:00","asset":"ETH","market_slug":"eth-updown-5m-1781805300","outcome":"Up","token_id":"84464230807213236425016885238522598164473602253759355671732117397567158540848","book":{"market":"0x87d522cbec7d7e644ec5485f60d464a56e7495b8797d51a2e9bb26d96d7c7f93","asset_id":"84464230807213236425016885238522598164473602253759355671732117397567158540848","timestamp":"1781805631004","hash":"95df5d3ed7a8452fc7a80b43d668c24c0c2f8e29","bids":[],"asks":[{"price":"0.99","size":"110800"},{"price":"0.98","size":"1744"},{"price":"0.97","size":"27"},{"price":"0.96","size":"26320"},{"price":"0.95","size":"16"},{"price":"0.94","size":"8000"},{"price":"0.93","size":"960"},{"price":"0.91","size":"999"},{"price":"0.9","size":"999"},{"price":"0.89","size":"2600"},{"price":"0.86","size":"2600"},{"price":"0.82","size":"999"},{"price":"0.81","size":"999"},{"price":"0.8","size":"500"},{"price":"0.74","size":"999"},{"price":"0.73","size":"999"},{"price":"0.7","size":"240"},{"price":"0.66","size":"999"},{"price":"0.65","size":"999"},{"price":"0.58","size":"2600"},{"price":"0.57","size":"2600"},{"price":"0.55","size":"160"},{"price":"0.46","size":"15"},{"price":"0.45","size":"1074"},{"price":"0.43","size":"999"},{"price":"0.35","size":"1029"},{"price":"0.3","size":"5"},{"price":"0.29","size":"2600"},{"price":"0.27","size":"2600"},{"price":"0.26","size":"17.25"},{"price":"0.23","size":"999"},{"price":"0.21","size":"999"},{"price":"0.17","size":"10"},{"price":"0.16","size":"999"},{"price":"0.09","size":"1999"},{"price":"0.08","size":"1999"},{"price":"0.05","size":"2010.26"},{"price":"0.04","size":"2000"},{"price":"0.03","size":"5"},{"price":"0.02","size":"55.4"},{"price":"0.01","size":"564542.2"}],"min_order_size":"5","tick_size":"0.01","neg_risk":false,"last_trade_price":"0.990"}}
{"sample_number":2,"sample_utc":"2026-06-18T18:00:38.6342190+00:00","asset":"ETH","market_slug":"eth-updown-5m-1781805300","outcome":"Down","token_id":"36868621506353927085332735174569787095878720872195622300005980530115725386975","book":{"market":"0x87d522cbec7d7e644ec5485f60d464a56e7495b8797d51a2e9bb26d96d7c7f93","asset_id":"36868621506353927085332735174569787095878720872195622300005980530115725386975","timestamp":"1781805631004","hash":"d93b534018cce0d117d9dfbcacc0c65143c0c774","bids":[{"price":"0.01","size":"110800"},{"price":"0.02","size":"1744"},{"price":"0.03","size":"27"},{"price":"0.04","size":"26320"},{"price":"0.05","size":"16"},{"price":"0.06","size":"8000"},{"price":"0.07","size":"960"},{"price":"0.09","size":"999"},{"price":"0.1","size":"999"},{"price":"0.11","size":"2600"},{"price":"0.14","size":"2600"},{"price":"0.18","size":"999"},{"price":"0.19","size":"999"},{"price":"0.2","size":"500"},{"price":"0.26","size":"999"},{"price":"0.27","size":"999"},{"price":"0.3","size":"240"},{"price":"0.34","size":"999"},{"price":"0.35","size":"999"},{"price":"0.42","size":"2600"},{"price":"0.43","size":"2600"},{"price":"0.45","size":"160"},{"price":"0.54","size":"15"},{"price":"0.55","size":"1074"},{"price":"0.57","size":"999"},{"price":"0.65","size":"1029"},{"price":"0.7","size":"5"},{"price":"0.71","size":"2600"},{"price":"0.73","size":"2600"},{"price":"0.74","size":"17.25"},{"price":"0.77","size":"999"},{"price":"0.79","size":"999"},{"price":"0.83","size":"10"},{"price":"0.84","size":"999"},{"price":"0.91","size":"1999"},{"price":"0.92","size":"1999"},{"price":"0.95","size":"2010.26"},{"price":"0.96","size":"2000"},{"price":"0.97","size":"5"},{"price":"0.98","size":"55.4"},{"price":"0.99","size":"564542.2"}],"asks":[],"min_order_size":"5","tick_size":"0.01","neg_risk":false,"last_trade_price":"0.990"}}
{"sample_number":2,"sample_utc":"2026-06-18T18:00:38.6342190+00:00","asset":"SOL","market_slug":"sol-updown-5m-1781805300","outcome":"Up","token_id":"43590587833960170489458633973229110190958133890499213708362021339678110080916","book":{"market":"0xa2a7fbb7f3fed9031df9d75228fbf4bfddbc4e8cc4f1fb9015ee7afa5a8bfcef","asset_id":"43590587833960170489458633973229110190958133890499213708362021339678110080916","timestamp":"1781805632445","hash":"4c0dd4078f3a0eb50309e5559788e318c432713e","bids":[],"asks":[{"price":"0.99","size":"110434"},{"price":"0.98","size":"1389"},{"price":"0.97","size":"27"},{"price":"0.96","size":"25670"},{"price":"0.95","size":"16"},{"price":"0.94","size":"8000"},{"price":"0.93","size":"480"},{"price":"0.91","size":"999"},{"price":"0.9","size":"999"},{"price":"0.89","size":"2600"},{"price":"0.86","size":"2600"},{"price":"0.82","size":"999"},{"price":"0.81","size":"999"},{"price":"0.8","size":"250"},{"price":"0.74","size":"999"},{"price":"0.73","size":"999"},{"price":"0.7","size":"120"},{"price":"0.66","size":"999"},{"price":"0.65","size":"999"},{"price":"0.58","size":"2600"},{"price":"0.57","size":"2600"},{"price":"0.55","size":"80"},{"price":"0.45","size":"1029"},{"price":"0.43","size":"999"},{"price":"0.35","size":"1014"},{"price":"0.29","size":"2600"},{"price":"0.27","size":"2600"},{"price":"0.23","size":"999"},{"price":"0.21","size":"999"},{"price":"0.16","size":"999"},{"price":"0.09","size":"1999"},{"price":"0.08","size":"1999"},{"price":"0.05","size":"2005"},{"price":"0.04","size":"2000"},{"price":"0.02","size":"112"},{"price":"0.01","size":"466868.77"}],"min_order_size":"5","tick_size":"0.01","neg_risk":false,"last_trade_price":"0.990"}}
{"sample_number":2,"sample_utc":"2026-06-18T18:00:38.6342190+00:00","asset":"SOL","market_slug":"sol-updown-5m-1781805300","outcome":"Down","token_id":"64729861947531231910320495939117410106727761033132301855694367299130238199956","book":{"market":"0xa2a7fbb7f3fed9031df9d75228fbf4bfddbc4e8cc4f1fb9015ee7afa5a8bfcef","asset_id":"64729861947531231910320495939117410106727761033132301855694367299130238199956","timestamp":"1781805632445","hash":"a3075a7ca412b77feef31f03817d52fe12833564","bids":[{"price":"0.01","size":"110434"},{"price":"0.02","size":"1389"},{"price":"0.03","size":"27"},{"price":"0.04","size":"25670"},{"price":"0.05","size":"16"},{"price":"0.06","size":"8000"},{"price":"0.07","size":"480"},{"price":"0.09","size":"999"},{"price":"0.1","size":"999"},{"price":"0.11","size":"2600"},{"price":"0.14","size":"2600"},{"price":"0.18","size":"999"},{"price":"0.19","size":"999"},{"price":"0.2","size":"250"},{"price":"0.26","size":"999"},{"price":"0.27","size":"999"},{"price":"0.3","size":"120"},{"price":"0.34","size":"999"},{"price":"0.35","size":"999"},{"price":"0.42","size":"2600"},{"price":"0.43","size":"2600"},{"price":"0.45","size":"80"},{"price":"0.55","size":"1029"},{"price":"0.57","size":"999"},{"price":"0.65","size":"1014"},{"price":"0.71","size":"2600"},{"price":"0.73","size":"2600"},{"price":"0.77","size":"999"},{"price":"0.79","size":"999"},{"price":"0.84","size":"999"},{"price":"0.91","size":"1999"},{"price":"0.92","size":"1999"},{"price":"0.95","size":"2005"},{"price":"0.96","size":"2000"},{"price":"0.98","size":"112"},{"price":"0.99","size":"466868.77"}],"asks":[],"min_order_size":"5","tick_size":"0.01","neg_risk":false,"last_trade_price":"0.990"}}
{"sample_number":3,"sample_utc":"2026-06-18T18:01:12.1506192+00:00","asset":"BTC","market_slug":"btc-updown-5m-1781805300","outcome":"Up","token_id":"100366993284555439229136263731142874057115468471011666953870421192847222766172","book":{"market":"0xa29dcb1f54b9d4e75465fcab657a4928c3952dad4b4828bcd9944e11f2b1d070","asset_id":"100366993284555439229136263731142874057115468471011666953870421192847222766172","timestamp":"1781805662645","hash":"229f2998d97e2f6cda258705bff48232ce4b4144","bids":[],"asks":[{"price":"0.99","size":"112834.7"},{"price":"0.98","size":"4218.57"},{"price":"0.97","size":"37"},{"price":"0.96","size":"26911.75"},{"price":"0.95","size":"30101"},{"price":"0.94","size":"8036"},{"price":"0.93","size":"1336"},{"price":"0.92","size":"1034"},{"price":"0.91","size":"3004"},{"price":"0.9","size":"3042"},{"price":"0.89","size":"2605"},{"price":"0.88","size":"7018"},{"price":"0.87","size":"5"},{"price":"0.86","size":"2605"},{"price":"0.85","size":"5"},{"price":"0.84","size":"5"},{"price":"0.83","size":"5"},{"price":"0.82","size":"3004"},{"price":"0.81","size":"3004"},{"price":"0.8","size":"692"},{"price":"0.79","size":"3004"},{"price":"0.78","size":"5"},{"price":"0.77","size":"5"},{"price":"0.76","size":"3004"},{"price":"0.75","size":"5"},{"price":"0.74","size":"2004"},{"price":"0.73","size":"2004"},{"price":"0.72","size":"5"},{"price":"0.71","size":"5"},{"price":"0.7","size":"646"},{"price":"0.69","size":"3004"},{"price":"0.68","size":"5"},{"price":"0.67","size":"5"},{"price":"0.66","size":"2004"},{"price":"0.65","size":"2004"},{"price":"0.64","size":"5"},{"price":"0.63","size":"5"},{"price":"0.62","size":"5"},{"price":"0.61","size":"5"},{"price":"0.6","size":"31"},{"price":"0.59","size":"5"},{"price":"0.58","size":"2605"},{"price":"0.57","size":"2605"},{"price":"0.56","size":"5"},{"price":"0.55","size":"225"},{"price":"0.52","size":"20"},{"price":"0.51","size":"28.99"},{"price":"0.5","size":"32"},{"price":"0.49","size":"2000"},{"price":"0.47","size":"1999"},{"price":"0.45","size":"2081"},{"price":"0.43","size":"1999"},{"price":"0.39","size":"1999"},{"price":"0.38","size":"5"},{"price":"0.37","size":"5"},{"price":"0.35","size":"2045"},{"price":"0.32","size":"1999"},{"price":"0.29","size":"2600"},{"price":"0.28","size":"5"},{"price":"0.27","size":"2605"},{"price":"0.25","size":"1634.1"},{"price":"0.23","size":"1999"},{"price":"0.21","size":"1999"},{"price":"0.16","size":"2059"},{"price":"0.15","size":"23.97"},{"price":"0.11","size":"1999"},{"price":"0.09","size":"1999"},{"price":"0.08","size":"1999"},{"price":"0.07","size":"1605"},{"price":"0.05","size":"2015"},{"price":"0.04","size":"2000"},{"price":"0.03","size":"15.05"},{"price":"0.02","size":"1650"},{"price":"0.01","size":"895702.09"}],"min_order_size":"5","tick_size":"0.01","neg_risk":false,"last_trade_price":"0.990"}}
{"sample_number":3,"sample_utc":"2026-06-18T18:01:12.1506192+00:00","asset":"BTC","market_slug":"btc-updown-5m-1781805300","outcome":"Down","token_id":"30945358799682125975622752445436537816479585992099959750063279707586060979279","book":{"market":"0xa29dcb1f54b9d4e75465fcab657a4928c3952dad4b4828bcd9944e11f2b1d070","asset_id":"30945358799682125975622752445436537816479585992099959750063279707586060979279","timestamp":"1781805662645","hash":"4f18d7f2beb08b15457d1c65216845a433a348c4","bids":[{"price":"0.01","size":"112834.7"},{"price":"0.02","size":"4218.57"},{"price":"0.03","size":"37"},{"price":"0.04","size":"26911.75"},{"price":"0.05","size":"30101"},{"price":"0.06","size":"8036"},{"price":"0.07","size":"1336"},{"price":"0.08","size":"1034"},{"price":"0.09","size":"3004"},{"price":"0.1","size":"3042"},{"price":"0.11","size":"2605"},{"price":"0.12","size":"7018"},{"price":"0.13","size":"5"},{"price":"0.14","size":"2605"},{"price":"0.15","size":"5"},{"price":"0.16","size":"5"},{"price":"0.17","size":"5"},{"price":"0.18","size":"3004"},{"price":"0.19","size":"3004"},{"price":"0.2","size":"692"},{"price":"0.21","size":"3004"},{"price":"0.22","size":"5"},{"price":"0.23","size":"5"},{"price":"0.24","size":"3004"},{"price":"0.25","size":"5"},{"price":"0.26","size":"2004"},{"price":"0.27","size":"2004"},{"price":"0.28","size":"5"},{"price":"0.29","size":"5"},{"price":"0.3","size":"646"},{"price":"0.31","size":"3004"},{"price":"0.32","size":"5"},{"price":"0.33","size":"5"},{"price":"0.34","size":"2004"},{"price":"0.35","size":"2004"},{"price":"0.36","size":"5"},{"price":"0.37","size":"5"},{"price":"0.38","size":"5"},{"price":"0.39","size":"5"},{"price":"0.4","size":"31"},{"price":"0.41","size":"5"},{"price":"0.42","size":"2605"},{"price":"0.43","size":"2605"},{"price":"0.44","size":"5"},{"price":"0.45","size":"225"},{"price":"0.48","size":"20"},{"price":"0.49","size":"28.99"},{"price":"0.5","size":"32"},{"price":"0.51","size":"2000"},{"price":"0.53","size":"1999"},{"price":"0.55","size":"2081"},{"price":"0.57","size":"1999"},{"price":"0.61","size":"1999"},{"price":"0.62","size":"5"},{"price":"0.63","size":"5"},{"price":"0.65","size":"2045"},{"price":"0.68","size":"1999"},{"price":"0.71","size":"2600"},{"price":"0.72","size":"5"},{"price":"0.73","size":"2605"},{"price":"0.75","size":"1634.1"},{"price":"0.77","size":"1999"},{"price":"0.79","size":"1999"},{"price":"0.84","size":"2059"},{"price":"0.85","size":"23.97"},{"price":"0.89","size":"1999"},{"price":"0.91","size":"1999"},{"price":"0.92","size":"1999"},{"price":"0.93","size":"1605"},{"price":"0.95","size":"2015"},{"price":"0.96","size":"2000"},{"price":"0.97","size":"15.05"},{"price":"0.98","size":"1650"},{"price":"0.99","size":"895702.09"}],"asks":[],"min_order_size":"5","tick_size":"0.01","neg_risk":false,"last_trade_price":"0.990"}}
{"sample_number":3,"sample_utc":"2026-06-18T18:01:12.1506192+00:00","asset":"ETH","market_slug":"eth-updown-5m-1781805300","outcome":"Up","token_id":"84464230807213236425016885238522598164473602253759355671732117397567158540848","book":{"market":"0x87d522cbec7d7e644ec5485f60d464a56e7495b8797d51a2e9bb26d96d7c7f93","asset_id":"84464230807213236425016885238522598164473602253759355671732117397567158540848","timestamp":"1781805673520","hash":"5e734958cb1ea8999431fd5b2fe57b9953696e60","bids":[],"asks":[{"price":"0.99","size":"110795"},{"price":"0.98","size":"1744"},{"price":"0.97","size":"27"},{"price":"0.96","size":"26320"},{"price":"0.95","size":"16"},{"price":"0.94","size":"8000"},{"price":"0.93","size":"960"},{"price":"0.91","size":"999"},{"price":"0.9","size":"999"},{"price":"0.89","size":"2600"},{"price":"0.86","size":"2600"},{"price":"0.82","size":"999"},{"price":"0.81","size":"999"},{"price":"0.8","size":"500"},{"price":"0.74","size":"999"},{"price":"0.73","size":"999"},{"price":"0.7","size":"240"},{"price":"0.66","size":"999"},{"price":"0.65","size":"999"},{"price":"0.58","size":"2600"},{"price":"0.57","size":"2600"},{"price":"0.55","size":"160"},{"price":"0.46","size":"15"},{"price":"0.45","size":"1074"},{"price":"0.43","size":"999"},{"price":"0.35","size":"1029"},{"price":"0.3","size":"5"},{"price":"0.29","size":"2600"},{"price":"0.27","size":"2600"},{"price":"0.26","size":"17.25"},{"price":"0.23","size":"999"},{"price":"0.21","size":"999"},{"price":"0.17","size":"10"},{"price":"0.16","size":"999"},{"price":"0.09","size":"1999"},{"price":"0.08","size":"1999"},{"price":"0.05","size":"2010.26"},{"price":"0.04","size":"2000"},{"price":"0.03","size":"5"},{"price":"0.02","size":"55.4"},{"price":"0.01","size":"563871.2"}],"min_order_size":"5","tick_size":"0.01","neg_risk":false,"last_trade_price":"0.990"}}
{"sample_number":3,"sample_utc":"2026-06-18T18:01:12.1506192+00:00","asset":"ETH","market_slug":"eth-updown-5m-1781805300","outcome":"Down","token_id":"36868621506353927085332735174569787095878720872195622300005980530115725386975","book":{"market":"0x87d522cbec7d7e644ec5485f60d464a56e7495b8797d51a2e9bb26d96d7c7f93","asset_id":"36868621506353927085332735174569787095878720872195622300005980530115725386975","timestamp":"1781805673520","hash":"23cf61c6a08a8680584327405730cac6cac30529","bids":[{"price":"0.01","size":"110795"},{"price":"0.02","size":"1744"},{"price":"0.03","size":"27"},{"price":"0.04","size":"26320"},{"price":"0.05","size":"16"},{"price":"0.06","size":"8000"},{"price":"0.07","size":"960"},{"price":"0.09","size":"999"},{"price":"0.1","size":"999"},{"price":"0.11","size":"2600"},{"price":"0.14","size":"2600"},{"price":"0.18","size":"999"},{"price":"0.19","size":"999"},{"price":"0.2","size":"500"},{"price":"0.26","size":"999"},{"price":"0.27","size":"999"},{"price":"0.3","size":"240"},{"price":"0.34","size":"999"},{"price":"0.35","size":"999"},{"price":"0.42","size":"2600"},{"price":"0.43","size":"2600"},{"price":"0.45","size":"160"},{"price":"0.54","size":"15"},{"price":"0.55","size":"1074"},{"price":"0.57","size":"999"},{"price":"0.65","size":"1029"},{"price":"0.7","size":"5"},{"price":"0.71","size":"2600"},{"price":"0.73","size":"2600"},{"price":"0.74","size":"17.25"},{"price":"0.77","size":"999"},{"price":"0.79","size":"999"},{"price":"0.83","size":"10"},{"price":"0.84","size":"999"},{"price":"0.91","size":"1999"},{"price":"0.92","size":"1999"},{"price":"0.95","size":"2010.26"},{"price":"0.96","size":"2000"},{"price":"0.97","size":"5"},{"price":"0.98","size":"55.4"},{"price":"0.99","size":"563871.2"}],"asks":[],"min_order_size":"5","tick_size":"0.01","neg_risk":false,"last_trade_price":"0.990"}}
{"sample_number":3,"sample_utc":"2026-06-18T18:01:12.1506192+00:00","asset":"SOL","market_slug":"sol-updown-5m-1781805300","outcome":"Up","token_id":"43590587833960170489458633973229110190958133890499213708362021339678110080916","book":{"market":"0xa2a7fbb7f3fed9031df9d75228fbf4bfddbc4e8cc4f1fb9015ee7afa5a8bfcef","asset_id":"43590587833960170489458633973229110190958133890499213708362021339678110080916","timestamp":"1781805660367","hash":"480b8426d76a0da5107ac74d68d0bad9a62b042e","bids":[],"asks":[{"price":"0.99","size":"110434"},{"price":"0.98","size":"1389"},{"price":"0.97","size":"27"},{"price":"0.96","size":"25670"},{"price":"0.95","size":"16"},{"price":"0.94","size":"8000"},{"price":"0.93","size":"480"},{"price":"0.91","size":"999"},{"price":"0.9","size":"999"},{"price":"0.89","size":"2600"},{"price":"0.86","size":"2600"},{"price":"0.82","size":"999"},{"price":"0.81","size":"999"},{"price":"0.8","size":"250"},{"price":"0.74","size":"999"},{"price":"0.73","size":"999"},{"price":"0.7","size":"120"},{"price":"0.66","size":"999"},{"price":"0.65","size":"999"},{"price":"0.58","size":"2600"},{"price":"0.57","size":"2600"},{"price":"0.55","size":"80"},{"price":"0.45","size":"1029"},{"price":"0.43","size":"999"},{"price":"0.35","size":"1014"},{"price":"0.29","size":"2600"},{"price":"0.27","size":"2600"},{"price":"0.23","size":"999"},{"price":"0.21","size":"999"},{"price":"0.16","size":"999"},{"price":"0.09","size":"1999"},{"price":"0.08","size":"1999"},{"price":"0.05","size":"2005"},{"price":"0.04","size":"2000"},{"price":"0.02","size":"112"},{"price":"0.01","size":"466848.77"}],"min_order_size":"5","tick_size":"0.01","neg_risk":false,"last_trade_price":"0.990"}}
{"sample_number":3,"sample_utc":"2026-06-18T18:01:12.1506192+00:00","asset":"SOL","market_slug":"sol-updown-5m-1781805300","outcome":"Down","token_id":"64729861947531231910320495939117410106727761033132301855694367299130238199956","book":{"market":"0xa2a7fbb7f3fed9031df9d75228fbf4bfddbc4e8cc4f1fb9015ee7afa5a8bfcef","asset_id":"64729861947531231910320495939117410106727761033132301855694367299130238199956","timestamp":"1781805660367","hash":"ba25557ac9b71139ca2c537b7734d6a278515eff","bids":[{"price":"0.01","size":"110434"},{"price":"0.02","size":"1389"},{"price":"0.03","size":"27"},{"price":"0.04","size":"25670"},{"price":"0.05","size":"16"},{"price":"0.06","size":"8000"},{"price":"0.07","size":"480"},{"price":"0.09","size":"999"},{"price":"0.1","size":"999"},{"price":"0.11","size":"2600"},{"price":"0.14","size":"2600"},{"price":"0.18","size":"999"},{"price":"0.19","size":"999"},{"price":"0.2","size":"250"},{"price":"0.26","size":"999"},{"price":"0.27","size":"999"},{"price":"0.3","size":"120"},{"price":"0.34","size":"999"},{"price":"0.35","size":"999"},{"price":"0.42","size":"2600"},{"price":"0.43","size":"2600"},{"price":"0.45","size":"80"},{"price":"0.55","size":"1029"},{"price":"0.57","size":"999"},{"price":"0.65","size":"1014"},{"price":"0.71","size":"2600"},{"price":"0.73","size":"2600"},{"price":"0.77","size":"999"},{"price":"0.79","size":"999"},{"price":"0.84","size":"999"},{"price":"0.91","size":"1999"},{"price":"0.92","size":"1999"},{"price":"0.95","size":"2005"},{"price":"0.96","size":"2000"},{"price":"0.98","size":"112"},{"price":"0.99","size":"466848.77"}],"asks":[],"min_order_size":"5","tick_size":"0.01","neg_risk":false,"last_trade_price":"0.990"}}
{"sample_number":4,"sample_utc":"2026-06-18T18:01:46.7054402+00:00","asset":"BTC","market_slug":"btc-updown-5m-1781805300","outcome":"Up","token_id":"100366993284555439229136263731142874057115468471011666953870421192847222766172","book":{"market":"0xa29dcb1f54b9d4e75465fcab657a4928c3952dad4b4828bcd9944e11f2b1d070","asset_id":"100366993284555439229136263731142874057115468471011666953870421192847222766172","timestamp":"1781805695200","hash":"56e194deb4c09416491f97b4b60d3d7803741886","bids":[],"asks":[{"price":"0.999","size":"115"},{"price":"0.99","size":"112854.7"},{"price":"0.98","size":"4218.57"},{"price":"0.97","size":"37"},{"price":"0.96","size":"26911.75"},{"price":"0.95","size":"30101"},{"price":"0.94","size":"8036"},{"price":"0.93","size":"1336"},{"price":"0.92","size":"1034"},{"price":"0.91","size":"3004"},{"price":"0.9","size":"3042"},{"price":"0.89","size":"2605"},{"price":"0.88","size":"7004"},{"price":"0.87","size":"5"},{"price":"0.86","size":"2605"},{"price":"0.85","size":"5"},{"price":"0.84","size":"5"},{"price":"0.83","size":"5"},{"price":"0.82","size":"3004"},{"price":"0.81","size":"3004"},{"price":"0.8","size":"692"},{"price":"0.79","size":"3004"},{"price":"0.78","size":"5"},{"price":"0.77","size":"5"},{"price":"0.76","size":"3004"},{"price":"0.75","size":"5"},{"price":"0.74","size":"2004"},{"price":"0.73","size":"2004"},{"price":"0.72","size":"5"},{"price":"0.71","size":"5"},{"price":"0.7","size":"646"},{"price":"0.69","size":"3004"},{"price":"0.68","size":"5"},{"price":"0.67","size":"5"},{"price":"0.66","size":"2004"},{"price":"0.65","size":"2004"},{"price":"0.64","size":"5"},{"price":"0.63","size":"5"},{"price":"0.62","size":"5"},{"price":"0.61","size":"5"},{"price":"0.6","size":"31"},{"price":"0.59","size":"5"},{"price":"0.58","size":"2605"},{"price":"0.57","size":"2605"},{"price":"0.56","size":"5"},{"price":"0.55","size":"225"},{"price":"0.52","size":"20"},{"price":"0.51","size":"28.99"},{"price":"0.5","size":"32"},{"price":"0.49","size":"2000"},{"price":"0.47","size":"1999"},{"price":"0.45","size":"2081"},{"price":"0.43","size":"1999"},{"price":"0.39","size":"1999"},{"price":"0.38","size":"5"},{"price":"0.37","size":"5"},{"price":"0.35","size":"2045"},{"price":"0.32","size":"1999"},{"price":"0.29","size":"2600"},{"price":"0.28","size":"5"},{"price":"0.27","size":"2605"},{"price":"0.25","size":"1634.1"},{"price":"0.23","size":"1999"},{"price":"0.21","size":"1999"},{"price":"0.16","size":"2059"},{"price":"0.15","size":"23.97"},{"price":"0.11","size":"1999"},{"price":"0.09","size":"1999"},{"price":"0.08","size":"1999"},{"price":"0.07","size":"1605"},{"price":"0.05","size":"2015"},{"price":"0.04","size":"2000"},{"price":"0.03","size":"15.05"},{"price":"0.02","size":"1650"},{"price":"0.01","size":"893794.39"},{"price":"0.009","size":"80"},{"price":"0.001","size":"330715.6"}],"min_order_size":"5","tick_size":"0.001","neg_risk":false,"last_trade_price":"0.990"}}
{"sample_number":4,"sample_utc":"2026-06-18T18:01:46.7054402+00:00","asset":"BTC","market_slug":"btc-updown-5m-1781805300","outcome":"Down","token_id":"30945358799682125975622752445436537816479585992099959750063279707586060979279","book":{"market":"0xa29dcb1f54b9d4e75465fcab657a4928c3952dad4b4828bcd9944e11f2b1d070","asset_id":"30945358799682125975622752445436537816479585992099959750063279707586060979279","timestamp":"1781805695200","hash":"1cc4f0ef4e54ae5a7ff7f9acfbd7a13ad371e3fe","bids":[{"price":"0.001","size":"115"},{"price":"0.01","size":"112854.7"},{"price":"0.02","size":"4218.57"},{"price":"0.03","size":"37"},{"price":"0.04","size":"26911.75"},{"price":"0.05","size":"30101"},{"price":"0.06","size":"8036"},{"price":"0.07","size":"1336"},{"price":"0.08","size":"1034"},{"price":"0.09","size":"3004"},{"price":"0.1","size":"3042"},{"price":"0.11","size":"2605"},{"price":"0.12","size":"7004"},{"price":"0.13","size":"5"},{"price":"0.14","size":"2605"},{"price":"0.15","size":"5"},{"price":"0.16","size":"5"},{"price":"0.17","size":"5"},{"price":"0.18","size":"3004"},{"price":"0.19","size":"3004"},{"price":"0.2","size":"692"},{"price":"0.21","size":"3004"},{"price":"0.22","size":"5"},{"price":"0.23","size":"5"},{"price":"0.24","size":"3004"},{"price":"0.25","size":"5"},{"price":"0.26","size":"2004"},{"price":"0.27","size":"2004"},{"price":"0.28","size":"5"},{"price":"0.29","size":"5"},{"price":"0.3","size":"646"},{"price":"0.31","size":"3004"},{"price":"0.32","size":"5"},{"price":"0.33","size":"5"},{"price":"0.34","size":"2004"},{"price":"0.35","size":"2004"},{"price":"0.36","size":"5"},{"price":"0.37","size":"5"},{"price":"0.38","size":"5"},{"price":"0.39","size":"5"},{"price":"0.4","size":"31"},{"price":"0.41","size":"5"},{"price":"0.42","size":"2605"},{"price":"0.43","size":"2605"},{"price":"0.44","size":"5"},{"price":"0.45","size":"225"},{"price":"0.48","size":"20"},{"price":"0.49","size":"28.99"},{"price":"0.5","size":"32"},{"price":"0.51","size":"2000"},{"price":"0.53","size":"1999"},{"price":"0.55","size":"2081"},{"price":"0.57","size":"1999"},{"price":"0.61","size":"1999"},{"price":"0.62","size":"5"},{"price":"0.63","size":"5"},{"price":"0.65","size":"2045"},{"price":"0.68","size":"1999"},{"price":"0.71","size":"2600"},{"price":"0.72","size":"5"},{"price":"0.73","size":"2605"},{"price":"0.75","size":"1634.1"},{"price":"0.77","size":"1999"},{"price":"0.79","size":"1999"},{"price":"0.84","size":"2059"},{"price":"0.85","size":"23.97"},{"price":"0.89","size":"1999"},{"price":"0.91","size":"1999"},{"price":"0.92","size":"1999"},{"price":"0.93","size":"1605"},{"price":"0.95","size":"2015"},{"price":"0.96","size":"2000"},{"price":"0.97","size":"15.05"},{"price":"0.98","size":"1650"},{"price":"0.99","size":"893794.39"},{"price":"0.991","size":"80"},{"price":"0.999","size":"330715.6"}],"asks":[],"min_order_size":"5","tick_size":"0.001","neg_risk":false,"last_trade_price":"0.990"}}
{"sample_number":4,"sample_utc":"2026-06-18T18:01:46.7054402+00:00","asset":"ETH","market_slug":"eth-updown-5m-1781805300","outcome":"Up","token_id":"84464230807213236425016885238522598164473602253759355671732117397567158540848","book":{"market":"0x87d522cbec7d7e644ec5485f60d464a56e7495b8797d51a2e9bb26d96d7c7f93","asset_id":"84464230807213236425016885238522598164473602253759355671732117397567158540848","timestamp":"1781805707000","hash":"8fdc083be3b631b08418b73684326018178847ce","bids":[],"asks":[{"price":"0.999","size":"115"},{"price":"0.99","size":"110795"},{"price":"0.98","size":"1744"},{"price":"0.97","size":"27"},{"price":"0.96","size":"26320"},{"price":"0.95","size":"16"},{"price":"0.94","size":"8000"},{"price":"0.93","size":"960"},{"price":"0.91","size":"999"},{"price":"0.9","size":"999"},{"price":"0.89","size":"2600"},{"price":"0.86","size":"2600"},{"price":"0.82","size":"999"},{"price":"0.81","size":"999"},{"price":"0.8","size":"500"},{"price":"0.74","size":"999"},{"price":"0.73","size":"999"},{"price":"0.7","size":"240"},{"price":"0.66","size":"999"},{"price":"0.65","size":"999"},{"price":"0.58","size":"2600"},{"price":"0.57","size":"2600"},{"price":"0.55","size":"160"},{"price":"0.46","size":"15"},{"price":"0.45","size":"1074"},{"price":"0.43","size":"999"},{"price":"0.35","size":"1029"},{"price":"0.3","size":"5"},{"price":"0.29","size":"2600"},{"price":"0.27","size":"2600"},{"price":"0.26","size":"17.25"},{"price":"0.23","size":"999"},{"price":"0.21","size":"999"},{"price":"0.17","size":"10"},{"price":"0.16","size":"999"},{"price":"0.09","size":"1999"},{"price":"0.08","size":"1999"},{"price":"0.05","size":"2010.26"},{"price":"0.04","size":"2000"},{"price":"0.03","size":"5"},{"price":"0.02","size":"55.4"},{"price":"0.01","size":"561678.43"},{"price":"0.009","size":"80"},{"price":"0.001","size":"234859.45"}],"min_order_size":"5","tick_size":"0.001","neg_risk":false,"last_trade_price":"0.990"}}
{"sample_number":4,"sample_utc":"2026-06-18T18:01:46.7054402+00:00","asset":"ETH","market_slug":"eth-updown-5m-1781805300","outcome":"Down","token_id":"36868621506353927085332735174569787095878720872195622300005980530115725386975","book":{"market":"0x87d522cbec7d7e644ec5485f60d464a56e7495b8797d51a2e9bb26d96d7c7f93","asset_id":"36868621506353927085332735174569787095878720872195622300005980530115725386975","timestamp":"1781805707000","hash":"9d12975c1c08707f6c6ce10a3575738c17948853","bids":[{"price":"0.001","size":"115"},{"price":"0.01","size":"110795"},{"price":"0.02","size":"1744"},{"price":"0.03","size":"27"},{"price":"0.04","size":"26320"},{"price":"0.05","size":"16"},{"price":"0.06","size":"8000"},{"price":"0.07","size":"960"},{"price":"0.09","size":"999"},{"price":"0.1","size":"999"},{"price":"0.11","size":"2600"},{"price":"0.14","size":"2600"},{"price":"0.18","size":"999"},{"price":"0.19","size":"999"},{"price":"0.2","size":"500"},{"price":"0.26","size":"999"},{"price":"0.27","size":"999"},{"price":"0.3","size":"240"},{"price":"0.34","size":"999"},{"price":"0.35","size":"999"},{"price":"0.42","size":"2600"},{"price":"0.43","size":"2600"},{"price":"0.45","size":"160"},{"price":"0.54","size":"15"},{"price":"0.55","size":"1074"},{"price":"0.57","size":"999"},{"price":"0.65","size":"1029"},{"price":"0.7","size":"5"},{"price":"0.71","size":"2600"},{"price":"0.73","size":"2600"},{"price":"0.74","size":"17.25"},{"price":"0.77","size":"999"},{"price":"0.79","size":"999"},{"price":"0.83","size":"10"},{"price":"0.84","size":"999"},{"price":"0.91","size":"1999"},{"price":"0.92","size":"1999"},{"price":"0.95","size":"2010.26"},{"price":"0.96","size":"2000"},{"price":"0.97","size":"5"},{"price":"0.98","size":"55.4"},{"price":"0.99","size":"561678.43"},{"price":"0.991","size":"80"},{"price":"0.999","size":"234859.45"}],"asks":[],"min_order_size":"5","tick_size":"0.001","neg_risk":false,"last_trade_price":"0.990"}}
{"sample_number":4,"sample_utc":"2026-06-18T18:01:46.7054402+00:00","asset":"SOL","market_slug":"sol-updown-5m-1781805300","outcome":"Up","token_id":"43590587833960170489458633973229110190958133890499213708362021339678110080916","book":{"market":"0xa2a7fbb7f3fed9031df9d75228fbf4bfddbc4e8cc4f1fb9015ee7afa5a8bfcef","asset_id":"43590587833960170489458633973229110190958133890499213708362021339678110080916","timestamp":"1781805692024","hash":"6b40b8b20b03212cac99506d2679b75574fa13ba","bids":[],"asks":[{"price":"0.999","size":"115"},{"price":"0.99","size":"110434"},{"price":"0.98","size":"1389"},{"price":"0.97","size":"27"},{"price":"0.96","size":"25670"},{"price":"0.95","size":"16"},{"price":"0.94","size":"8000"},{"price":"0.93","size":"480"},{"price":"0.91","size":"999"},{"price":"0.9","size":"999"},{"price":"0.89","size":"2600"},{"price":"0.86","size":"2600"},{"price":"0.82","size":"999"},{"price":"0.81","size":"999"},{"price":"0.8","size":"250"},{"price":"0.74","size":"999"},{"price":"0.73","size":"999"},{"price":"0.7","size":"120"},{"price":"0.66","size":"999"},{"price":"0.65","size":"999"},{"price":"0.58","size":"2600"},{"price":"0.57","size":"2600"},{"price":"0.55","size":"80"},{"price":"0.45","size":"1029"},{"price":"0.43","size":"999"},{"price":"0.35","size":"1014"},{"price":"0.29","size":"2600"},{"price":"0.27","size":"2600"},{"price":"0.23","size":"999"},{"price":"0.21","size":"999"},{"price":"0.16","size":"999"},{"price":"0.09","size":"1999"},{"price":"0.08","size":"1999"},{"price":"0.05","size":"2005"},{"price":"0.04","size":"2000"},{"price":"0.02","size":"112"},{"price":"0.01","size":"465767.97"},{"price":"0.009","size":"80"},{"price":"0.001","size":"173406.52"}],"min_order_size":"5","tick_size":"0.001","neg_risk":false,"last_trade_price":"0.990"}}
{"sample_number":4,"sample_utc":"2026-06-18T18:01:46.7054402+00:00","asset":"SOL","market_slug":"sol-updown-5m-1781805300","outcome":"Down","token_id":"64729861947531231910320495939117410106727761033132301855694367299130238199956","book":{"market":"0xa2a7fbb7f3fed9031df9d75228fbf4bfddbc4e8cc4f1fb9015ee7afa5a8bfcef","asset_id":"64729861947531231910320495939117410106727761033132301855694367299130238199956","timestamp":"1781805692024","hash":"a0dd765396f9f5bf0ffc6c28a8e66cfe5ba266d1","bids":[{"price":"0.001","size":"115"},{"price":"0.01","size":"110434"},{"price":"0.02","size":"1389"},{"price":"0.03","size":"27"},{"price":"0.04","size":"25670"},{"price":"0.05","size":"16"},{"price":"0.06","size":"8000"},{"price":"0.07","size":"480"},{"price":"0.09","size":"999"},{"price":"0.1","size":"999"},{"price":"0.11","size":"2600"},{"price":"0.14","size":"2600"},{"price":"0.18","size":"999"},{"price":"0.19","size":"999"},{"price":"0.2","size":"250"},{"price":"0.26","size":"999"},{"price":"0.27","size":"999"},{"price":"0.3","size":"120"},{"price":"0.34","size":"999"},{"price":"0.35","size":"999"},{"price":"0.42","size":"2600"},{"price":"0.43","size":"2600"},{"price":"0.45","size":"80"},{"price":"0.55","size":"1029"},{"price":"0.57","size":"999"},{"price":"0.65","size":"1014"},{"price":"0.71","size":"2600"},{"price":"0.73","size":"2600"},{"price":"0.77","size":"999"},{"price":"0.79","size":"999"},{"price":"0.84","size":"999"},{"price":"0.91","size":"1999"},{"price":"0.92","size":"1999"},{"price":"0.95","size":"2005"},{"price":"0.96","size":"2000"},{"price":"0.98","size":"112"},{"price":"0.99","size":"465767.97"},{"price":"0.991","size":"80"},{"price":"0.999","size":"173406.52"}],"asks":[],"min_order_size":"5","tick_size":"0.001","neg_risk":false,"last_trade_price":"0.990"}}
{"sample_number":5,"sample_utc":"2026-06-18T18:02:21.1136942+00:00","asset":"BTC","market_slug":"btc-updown-5m-1781805300","outcome":"Up","token_id":"100366993284555439229136263731142874057115468471011666953870421192847222766172","book":{"market":"0xa29dcb1f54b9d4e75465fcab657a4928c3952dad4b4828bcd9944e11f2b1d070","asset_id":"100366993284555439229136263731142874057115468471011666953870421192847222766172","timestamp":"1781805741000","hash":"3190e8fa586c7c0c95f352f395a6a1f415942dee","bids":[],"asks":[{"price":"0.999","size":"115"},{"price":"0.99","size":"112734.7"},{"price":"0.98","size":"4218.57"},{"price":"0.97","size":"37"},{"price":"0.96","size":"26911.75"},{"price":"0.95","size":"30101"},{"price":"0.94","size":"8036"},{"price":"0.93","size":"1336"},{"price":"0.92","size":"1034"},{"price":"0.91","size":"3004"},{"price":"0.9","size":"3042"},{"price":"0.89","size":"2605"},{"price":"0.88","size":"7004"},{"price":"0.87","size":"5"},{"price":"0.86","size":"2605"},{"price":"0.85","size":"5"},{"price":"0.84","size":"5"},{"price":"0.83","size":"5"},{"price":"0.82","size":"3004"},{"price":"0.81","size":"3004"},{"price":"0.8","size":"692"},{"price":"0.79","size":"3004"},{"price":"0.78","size":"5"},{"price":"0.77","size":"5"},{"price":"0.76","size":"3004"},{"price":"0.75","size":"5"},{"price":"0.74","size":"2004"},{"price":"0.73","size":"2004"},{"price":"0.72","size":"5"},{"price":"0.71","size":"5"},{"price":"0.7","size":"646"},{"price":"0.69","size":"3004"},{"price":"0.68","size":"5"},{"price":"0.67","size":"5"},{"price":"0.66","size":"2004"},{"price":"0.65","size":"2004"},{"price":"0.64","size":"5"},{"price":"0.63","size":"5"},{"price":"0.62","size":"5"},{"price":"0.61","size":"5"},{"price":"0.6","size":"31"},{"price":"0.59","size":"5"},{"price":"0.58","size":"2605"},{"price":"0.57","size":"2605"},{"price":"0.56","size":"5"},{"price":"0.55","size":"225"},{"price":"0.52","size":"20"},{"price":"0.51","size":"28.99"},{"price":"0.5","size":"32"},{"price":"0.49","size":"2000"},{"price":"0.47","size":"1999"},{"price":"0.45","size":"2081"},{"price":"0.43","size":"1999"},{"price":"0.39","size":"1999"},{"price":"0.38","size":"5"},{"price":"0.37","size":"5"},{"price":"0.35","size":"2045"},{"price":"0.32","size":"1999"},{"price":"0.29","size":"2600"},{"price":"0.28","size":"5"},{"price":"0.27","size":"2605"},{"price":"0.25","size":"1634.1"},{"price":"0.23","size":"1999"},{"price":"0.21","size":"1999"},{"price":"0.16","size":"2059"},{"price":"0.15","size":"23.97"},{"price":"0.11","size":"1999"},{"price":"0.09","size":"1999"},{"price":"0.08","size":"1999"},{"price":"0.07","size":"1605"},{"price":"0.05","size":"2015"},{"price":"0.04","size":"2000"},{"price":"0.03","size":"15.05"},{"price":"0.02","size":"1600"},{"price":"0.01","size":"893378.57"},{"price":"0.009","size":"80"},{"price":"0.001","size":"330715.6"}],"min_order_size":"5","tick_size":"0.001","neg_risk":false,"last_trade_price":"0.990"}}
{"sample_number":5,"sample_utc":"2026-06-18T18:02:21.1136942+00:00","asset":"BTC","market_slug":"btc-updown-5m-1781805300","outcome":"Down","token_id":"30945358799682125975622752445436537816479585992099959750063279707586060979279","book":{"market":"0xa29dcb1f54b9d4e75465fcab657a4928c3952dad4b4828bcd9944e11f2b1d070","asset_id":"30945358799682125975622752445436537816479585992099959750063279707586060979279","timestamp":"1781805741000","hash":"c4ac7bd82d02b205e8ed7dddbe393da49597ed7a","bids":[{"price":"0.001","size":"115"},{"price":"0.01","size":"112734.7"},{"price":"0.02","size":"4218.57"},{"price":"0.03","size":"37"},{"price":"0.04","size":"26911.75"},{"price":"0.05","size":"30101"},{"price":"0.06","size":"8036"},{"price":"0.07","size":"1336"},{"price":"0.08","size":"1034"},{"price":"0.09","size":"3004"},{"price":"0.1","size":"3042"},{"price":"0.11","size":"2605"},{"price":"0.12","size":"7004"},{"price":"0.13","size":"5"},{"price":"0.14","size":"2605"},{"price":"0.15","size":"5"},{"price":"0.16","size":"5"},{"price":"0.17","size":"5"},{"price":"0.18","size":"3004"},{"price":"0.19","size":"3004"},{"price":"0.2","size":"692"},{"price":"0.21","size":"3004"},{"price":"0.22","size":"5"},{"price":"0.23","size":"5"},{"price":"0.24","size":"3004"},{"price":"0.25","size":"5"},{"price":"0.26","size":"2004"},{"price":"0.27","size":"2004"},{"price":"0.28","size":"5"},{"price":"0.29","size":"5"},{"price":"0.3","size":"646"},{"price":"0.31","size":"3004"},{"price":"0.32","size":"5"},{"price":"0.33","size":"5"},{"price":"0.34","size":"2004"},{"price":"0.35","size":"2004"},{"price":"0.36","size":"5"},{"price":"0.37","size":"5"},{"price":"0.38","size":"5"},{"price":"0.39","size":"5"},{"price":"0.4","size":"31"},{"price":"0.41","size":"5"},{"price":"0.42","size":"2605"},{"price":"0.43","size":"2605"},{"price":"0.44","size":"5"},{"price":"0.45","size":"225"},{"price":"0.48","size":"20"},{"price":"0.49","size":"28.99"},{"price":"0.5","size":"32"},{"price":"0.51","size":"2000"},{"price":"0.53","size":"1999"},{"price":"0.55","size":"2081"},{"price":"0.57","size":"1999"},{"price":"0.61","size":"1999"},{"price":"0.62","size":"5"},{"price":"0.63","size":"5"},{"price":"0.65","size":"2045"},{"price":"0.68","size":"1999"},{"price":"0.71","size":"2600"},{"price":"0.72","size":"5"},{"price":"0.73","size":"2605"},{"price":"0.75","size":"1634.1"},{"price":"0.77","size":"1999"},{"price":"0.79","size":"1999"},{"price":"0.84","size":"2059"},{"price":"0.85","size":"23.97"},{"price":"0.89","size":"1999"},{"price":"0.91","size":"1999"},{"price":"0.92","size":"1999"},{"price":"0.93","size":"1605"},{"price":"0.95","size":"2015"},{"price":"0.96","size":"2000"},{"price":"0.97","size":"15.05"},{"price":"0.98","size":"1600"},{"price":"0.99","size":"893378.57"},{"price":"0.991","size":"80"},{"price":"0.999","size":"330715.6"}],"asks":[],"min_order_size":"5","tick_size":"0.001","neg_risk":false,"last_trade_price":"0.990"}}
{"sample_number":5,"sample_utc":"2026-06-18T18:02:21.1136942+00:00","asset":"ETH","market_slug":"eth-updown-5m-1781805300","outcome":"Up","token_id":"84464230807213236425016885238522598164473602253759355671732117397567158540848","book":{"market":"0x87d522cbec7d7e644ec5485f60d464a56e7495b8797d51a2e9bb26d96d7c7f93","asset_id":"84464230807213236425016885238522598164473602253759355671732117397567158540848","timestamp":"1781805741000","hash":"bc51ca6aac290f0fccd6e72d9c3451a5141c7f8a","bids":[],"asks":[{"price":"0.999","size":"115"},{"price":"0.99","size":"110795"},{"price":"0.98","size":"1744"},{"price":"0.97","size":"27"},{"price":"0.96","size":"26320"},{"price":"0.95","size":"16"},{"price":"0.94","size":"8000"},{"price":"0.93","size":"960"},{"price":"0.91","size":"999"},{"price":"0.9","size":"999"},{"price":"0.89","size":"2600"},{"price":"0.86","size":"2600"},{"price":"0.82","size":"999"},{"price":"0.81","size":"999"},{"price":"0.8","size":"500"},{"price":"0.74","size":"999"},{"price":"0.73","size":"999"},{"price":"0.7","size":"240"},{"price":"0.66","size":"999"},{"price":"0.65","size":"999"},{"price":"0.58","size":"2600"},{"price":"0.57","size":"2600"},{"price":"0.55","size":"160"},{"price":"0.46","size":"15"},{"price":"0.45","size":"1074"},{"price":"0.43","size":"999"},{"price":"0.35","size":"1029"},{"price":"0.3","size":"5"},{"price":"0.29","size":"2600"},{"price":"0.27","size":"2600"},{"price":"0.26","size":"17.25"},{"price":"0.23","size":"999"},{"price":"0.21","size":"999"},{"price":"0.16","size":"999"},{"price":"0.09","size":"1999"},{"price":"0.08","size":"1999"},{"price":"0.05","size":"2010.26"},{"price":"0.04","size":"2000"},{"price":"0.03","size":"5"},{"price":"0.02","size":"55.4"},{"price":"0.01","size":"561172.61"},{"price":"0.009","size":"80"},{"price":"0.001","size":"234859.45"}],"min_order_size":"5","tick_size":"0.001","neg_risk":false,"last_trade_price":"0.990"}}
{"sample_number":5,"sample_utc":"2026-06-18T18:02:21.1136942+00:00","asset":"ETH","market_slug":"eth-updown-5m-1781805300","outcome":"Down","token_id":"36868621506353927085332735174569787095878720872195622300005980530115725386975","book":{"market":"0x87d522cbec7d7e644ec5485f60d464a56e7495b8797d51a2e9bb26d96d7c7f93","asset_id":"36868621506353927085332735174569787095878720872195622300005980530115725386975","timestamp":"1781805741000","hash":"c6abc2aa5a7117632d245577cd111555806be54b","bids":[{"price":"0.001","size":"115"},{"price":"0.01","size":"110795"},{"price":"0.02","size":"1744"},{"price":"0.03","size":"27"},{"price":"0.04","size":"26320"},{"price":"0.05","size":"16"},{"price":"0.06","size":"8000"},{"price":"0.07","size":"960"},{"price":"0.09","size":"999"},{"price":"0.1","size":"999"},{"price":"0.11","size":"2600"},{"price":"0.14","size":"2600"},{"price":"0.18","size":"999"},{"price":"0.19","size":"999"},{"price":"0.2","size":"500"},{"price":"0.26","size":"999"},{"price":"0.27","size":"999"},{"price":"0.3","size":"240"},{"price":"0.34","size":"999"},{"price":"0.35","size":"999"},{"price":"0.42","size":"2600"},{"price":"0.43","size":"2600"},{"price":"0.45","size":"160"},{"price":"0.54","size":"15"},{"price":"0.55","size":"1074"},{"price":"0.57","size":"999"},{"price":"0.65","size":"1029"},{"price":"0.7","size":"5"},{"price":"0.71","size":"2600"},{"price":"0.73","size":"2600"},{"price":"0.74","size":"17.25"},{"price":"0.77","size":"999"},{"price":"0.79","size":"999"},{"price":"0.84","size":"999"},{"price":"0.91","size":"1999"},{"price":"0.92","size":"1999"},{"price":"0.95","size":"2010.26"},{"price":"0.96","size":"2000"},{"price":"0.97","size":"5"},{"price":"0.98","size":"55.4"},{"price":"0.99","size":"561172.61"},{"price":"0.991","size":"80"},{"price":"0.999","size":"234859.45"}],"asks":[],"min_order_size":"5","tick_size":"0.001","neg_risk":false,"last_trade_price":"0.990"}}
{"sample_number":5,"sample_utc":"2026-06-18T18:02:21.1136942+00:00","asset":"SOL","market_slug":"sol-updown-5m-1781805300","outcome":"Up","token_id":"43590587833960170489458633973229110190958133890499213708362021339678110080916","book":{"market":"0xa2a7fbb7f3fed9031df9d75228fbf4bfddbc4e8cc4f1fb9015ee7afa5a8bfcef","asset_id":"43590587833960170489458633973229110190958133890499213708362021339678110080916","timestamp":"1781805721000","hash":"7e03edf0bf3fb498f1be463c2075c0af56615f8e","bids":[],"asks":[{"price":"0.999","size":"115"},{"price":"0.99","size":"110434"},{"price":"0.98","size":"1389"},{"price":"0.97","size":"27"},{"price":"0.96","size":"25670"},{"price":"0.95","size":"16"},{"price":"0.94","size":"8000"},{"price":"0.93","size":"480"},{"price":"0.91","size":"999"},{"price":"0.9","size":"999"},{"price":"0.89","size":"2600"},{"price":"0.86","size":"2600"},{"price":"0.82","size":"999"},{"price":"0.81","size":"999"},{"price":"0.8","size":"250"},{"price":"0.74","size":"999"},{"price":"0.73","size":"999"},{"price":"0.7","size":"120"},{"price":"0.66","size":"999"},{"price":"0.65","size":"999"},{"price":"0.58","size":"2600"},{"price":"0.57","size":"2600"},{"price":"0.55","size":"80"},{"price":"0.45","size":"1029"},{"price":"0.43","size":"999"},{"price":"0.35","size":"1014"},{"price":"0.29","size":"2600"},{"price":"0.27","size":"2600"},{"price":"0.23","size":"999"},{"price":"0.21","size":"999"},{"price":"0.16","size":"999"},{"price":"0.09","size":"1999"},{"price":"0.08","size":"1999"},{"price":"0.05","size":"2005"},{"price":"0.04","size":"2000"},{"price":"0.02","size":"112"},{"price":"0.01","size":"465387.15"},{"price":"0.009","size":"80"},{"price":"0.001","size":"173406.52"}],"min_order_size":"5","tick_size":"0.001","neg_risk":false,"last_trade_price":"0.990"}}
{"sample_number":5,"sample_utc":"2026-06-18T18:02:21.1136942+00:00","asset":"SOL","market_slug":"sol-updown-5m-1781805300","outcome":"Down","token_id":"64729861947531231910320495939117410106727761033132301855694367299130238199956","book":{"market":"0xa2a7fbb7f3fed9031df9d75228fbf4bfddbc4e8cc4f1fb9015ee7afa5a8bfcef","asset_id":"64729861947531231910320495939117410106727761033132301855694367299130238199956","timestamp":"1781805721000","hash":"7ab884ce0263850951fdf9b16acabe2a8d5369b5","bids":[{"price":"0.001","size":"115"},{"price":"0.01","size":"110434"},{"price":"0.02","size":"1389"},{"price":"0.03","size":"27"},{"price":"0.04","size":"25670"},{"price":"0.05","size":"16"},{"price":"0.06","size":"8000"},{"price":"0.07","size":"480"},{"price":"0.09","size":"999"},{"price":"0.1","size":"999"},{"price":"0.11","size":"2600"},{"price":"0.14","size":"2600"},{"price":"0.18","size":"999"},{"price":"0.19","size":"999"},{"price":"0.2","size":"250"},{"price":"0.26","size":"999"},{"price":"0.27","size":"999"},{"price":"0.3","size":"120"},{"price":"0.34","size":"999"},{"price":"0.35","size":"999"},{"price":"0.42","size":"2600"},{"price":"0.43","size":"2600"},{"price":"0.45","size":"80"},{"price":"0.55","size":"1029"},{"price":"0.57","size":"999"},{"price":"0.65","size":"1014"},{"price":"0.71","size":"2600"},{"price":"0.73","size":"2600"},{"price":"0.77","size":"999"},{"price":"0.79","size":"999"},{"price":"0.84","size":"999"},{"price":"0.91","size":"1999"},{"price":"0.92","size":"1999"},{"price":"0.95","size":"2005"},{"price":"0.96","size":"2000"},{"price":"0.98","size":"112"},{"price":"0.99","size":"465387.15"},{"price":"0.991","size":"80"},{"price":"0.999","size":"173406.52"}],"asks":[],"min_order_size":"5","tick_size":"0.001","neg_risk":false,"last_trade_price":"0.990"}}
{"sample_number":9,"sample_utc":"2026-06-18T18:04:35.6721226+00:00","asset":"SOL","market_slug":"sol-updown-5m-1781805600","outcome":"Up","token_id":"92887202688210559890269037787373548518364039356424906092889842946664474809719","book":{"market":"0x240208a76cd02c37591e0b118ddd74d7caed524a1b0740d840fa5956862c2e6f","asset_id":"92887202688210559890269037787373548518364039356424906092889842946664474809719","timestamp":"1781805876762","hash":"9750e1f051af592359050f0cb208c008031fd088","bids":[],"asks":[{"price":"0.99","size":"1477.3"},{"price":"0.98","size":"468.3"},{"price":"0.97","size":"278.7"},{"price":"0.96","size":"160.9"},{"price":"0.95","size":"235.4"},{"price":"0.94","size":"130"},{"price":"0.93","size":"127"},{"price":"0.92","size":"86.7"},{"price":"0.91","size":"22.9"},{"price":"0.9","size":"76.4"},{"price":"0.89","size":"20.3"},{"price":"0.88","size":"19.3"},{"price":"0.87","size":"18.5"},{"price":"0.86","size":"52.8"},{"price":"0.85","size":"22.19"},{"price":"0.84","size":"16.69"},{"price":"0.83","size":"16.19"},{"price":"0.82","size":"15.8"},{"price":"0.81","size":"15.4"},{"price":"0.8","size":"20.1"},{"price":"0.79","size":"14.8"},{"price":"0.78","size":"14.6"},{"price":"0.77","size":"14.3"},{"price":"0.76","size":"14.1"},{"price":"0.75","size":"18.9"},{"price":"0.74","size":"13.8"},{"price":"0.73","size":"13.6"},{"price":"0.72","size":"13.4"},{"price":"0.71","size":"13.3"},{"price":"0.7","size":"18.2"},{"price":"0.69","size":"13.1"},{"price":"0.68","size":"13"},{"price":"0.67","size":"12.9"},{"price":"0.66","size":"12.8"},{"price":"0.65","size":"17.7"},{"price":"0.64","size":"12.6"},{"price":"0.63","size":"12.6"},{"price":"0.62","size":"12.5"},{"price":"0.61","size":"12.5"},{"price":"0.6","size":"17.4"},{"price":"0.59","size":"12.4"},{"price":"0.58","size":"12.3"},{"price":"0.57","size":"12.3"},{"price":"0.56","size":"12.3"},{"price":"0.55","size":"12.3"},{"price":"0.54","size":"12.2"},{"price":"0.53","size":"12.2"},{"price":"0.52","size":"12.2"},{"price":"0.51","size":"12.2"},{"price":"0.5","size":"12.2"},{"price":"0.49","size":"12.2"},{"price":"0.48","size":"12.2"},{"price":"0.47","size":"12.2"},{"price":"0.46","size":"12.2"},{"price":"0.45","size":"12.3"},{"price":"0.44","size":"12.3"},{"price":"0.43","size":"12.3"},{"price":"0.42","size":"12.3"},{"price":"0.41","size":"12.4"},{"price":"0.4","size":"12.4"},{"price":"0.39","size":"12.5"},{"price":"0.38","size":"12.5"},{"price":"0.37","size":"12.6"},{"price":"0.36","size":"12.6"},{"price":"0.35","size":"12.7"},{"price":"0.34","size":"12.8"},{"price":"0.33","size":"12.9"},{"price":"0.32","size":"13"},{"price":"0.31","size":"6.1"},{"price":"0.3","size":"13.2"},{"price":"0.29","size":"13.3"},{"price":"0.28","size":"13.4"},{"price":"0.27","size":"23.6"},{"price":"0.26","size":"13.8"},{"price":"0.25","size":"13.9"},{"price":"0.24","size":"14.1"},{"price":"0.23","size":"14.3"},{"price":"0.22","size":"14.6"},{"price":"0.21","size":"14.8"},{"price":"0.2","size":"15.1"},{"price":"0.19","size":"20.4"},{"price":"0.18","size":"15.8"},{"price":"0.17","size":"16.19"},{"price":"0.16","size":"16.69"},{"price":"0.15","size":"17.19"},{"price":"0.14","size":"17.8"},{"price":"0.13","size":"28.5"},{"price":"0.12","size":"19.3"},{"price":"0.11","size":"20.3"},{"price":"0.1","size":"215.4"},{"price":"0.09","size":"22.9"},{"price":"0.08","size":"24.7"},{"price":"0.07","size":"58.2"},{"price":"0.06","size":"47.92"},{"price":"0.05","size":"160.64"},{"price":"0.04","size":"51.82"},{"price":"0.03","size":"24.2"},{"price":"0.02","size":"33.8"},{"price":"0.01","size":"549.93"}],"min_order_size":"5","tick_size":"0.01","neg_risk":false,"last_trade_price":"0.990"}}
{"sample_number":9,"sample_utc":"2026-06-18T18:04:35.6721226+00:00","asset":"SOL","market_slug":"sol-updown-5m-1781805600","outcome":"Down","token_id":"42158671632333916299715271514496933316667556269910783091936524939668698929488","book":{"market":"0x240208a76cd02c37591e0b118ddd74d7caed524a1b0740d840fa5956862c2e6f","asset_id":"42158671632333916299715271514496933316667556269910783091936524939668698929488","timestamp":"1781805876936","hash":"6a2a88ba7cbc23e3b699453bfb257046ee6b1ec2","bids":[{"price":"0.01","size":"1467.3"},{"price":"0.02","size":"468.3"},{"price":"0.03","size":"278.7"},{"price":"0.04","size":"165.9"},{"price":"0.05","size":"235.4"},{"price":"0.06","size":"130"},{"price":"0.07","size":"127"},{"price":"0.08","size":"86.7"},{"price":"0.09","size":"22.9"},{"price":"0.1","size":"76.4"},{"price":"0.11","size":"20.3"},{"price":"0.12","size":"19.3"},{"price":"0.13","size":"18.5"},{"price":"0.14","size":"52.8"},{"price":"0.15","size":"22.19"},{"price":"0.16","size":"16.69"},{"price":"0.17","size":"16.19"},{"price":"0.18","size":"15.8"},{"price":"0.19","size":"15.4"},{"price":"0.2","size":"20.1"},{"price":"0.21","size":"14.8"},{"price":"0.22","size":"14.6"},{"price":"0.23","size":"14.3"},{"price":"0.24","size":"14.1"},{"price":"0.25","size":"18.9"},{"price":"0.26","size":"13.8"},{"price":"0.27","size":"13.6"},{"price":"0.28","size":"13.4"},{"price":"0.29","size":"13.3"},{"price":"0.3","size":"18.2"},{"price":"0.31","size":"13.1"},{"price":"0.32","size":"13"},{"price":"0.33","size":"12.9"},{"price":"0.34","size":"12.8"},{"price":"0.35","size":"17.7"},{"price":"0.36","size":"12.6"},{"price":"0.37","size":"12.6"},{"price":"0.38","size":"12.5"},{"price":"0.39","size":"12.5"},{"price":"0.4","size":"17.4"},{"price":"0.41","size":"12.4"},{"price":"0.42","size":"12.3"},{"price":"0.43","size":"12.3"},{"price":"0.44","size":"12.3"},{"price":"0.45","size":"12.3"},{"price":"0.46","size":"12.2"},{"price":"0.47","size":"12.2"},{"price":"0.48","size":"12.2"},{"price":"0.49","size":"12.2"},{"price":"0.5","size":"12.2"},{"price":"0.51","size":"12.2"},{"price":"0.52","size":"12.2"},{"price":"0.53","size":"12.2"},{"price":"0.54","size":"12.2"},{"price":"0.55","size":"12.3"},{"price":"0.56","size":"12.3"},{"price":"0.57","size":"12.3"},{"price":"0.58","size":"12.3"},{"price":"0.59","size":"12.4"},{"price":"0.6","size":"12.4"},{"price":"0.61","size":"12.5"},{"price":"0.62","size":"12.5"},{"price":"0.63","size":"12.6"},{"price":"0.64","size":"12.6"},{"price":"0.65","size":"12.7"},{"price":"0.66","size":"12.8"},{"price":"0.67","size":"12.9"},{"price":"0.68","size":"13"},{"price":"0.69","size":"6.1"},{"price":"0.7","size":"13.2"},{"price":"0.71","size":"13.3"},{"price":"0.72","size":"13.4"},{"price":"0.73","size":"23.6"},{"price":"0.74","size":"13.8"},{"price":"0.75","size":"13.9"},{"price":"0.76","size":"14.1"},{"price":"0.77","size":"14.3"},{"price":"0.78","size":"14.6"},{"price":"0.79","size":"14.8"},{"price":"0.8","size":"15.1"},{"price":"0.81","size":"20.4"},{"price":"0.82","size":"15.8"},{"price":"0.83","size":"16.19"},{"price":"0.84","size":"16.69"},{"price":"0.85","size":"17.19"},{"price":"0.86","size":"17.8"},{"price":"0.87","size":"28.5"},{"price":"0.88","size":"19.3"},{"price":"0.89","size":"20.3"},{"price":"0.9","size":"215.4"},{"price":"0.91","size":"22.9"},{"price":"0.92","size":"24.7"},{"price":"0.93","size":"58.2"},{"price":"0.94","size":"47.92"},{"price":"0.95","size":"160.64"},{"price":"0.96","size":"51.82"},{"price":"0.97","size":"24.2"},{"price":"0.98","size":"33.8"},{"price":"0.99","size":"549.93"}],"asks":[],"min_order_size":"5","tick_size":"0.01","neg_risk":false,"last_trade_price":"0.990"}}
{"sample_number":10,"sample_utc":"2026-06-18T18:05:09.6552535+00:00","asset":"SOL","market_slug":"sol-updown-5m-1781805600","outcome":"Up","token_id":"92887202688210559890269037787373548518364039356424906092889842946664474809719","book":{"market":"0x240208a76cd02c37591e0b118ddd74d7caed524a1b0740d840fa5956862c2e6f","asset_id":"92887202688210559890269037787373548518364039356424906092889842946664474809719","timestamp":"1781805907709","hash":"5962d84f704bfd0d0e8051ceae8037ddb4c2d382","bids":[],"asks":[{"price":"0.99","size":"110423"},{"price":"0.98","size":"1389"},{"price":"0.97","size":"27"},{"price":"0.96","size":"25670"},{"price":"0.95","size":"16"},{"price":"0.94","size":"8000"},{"price":"0.93","size":"480"},{"price":"0.91","size":"999"},{"price":"0.9","size":"999"},{"price":"0.89","size":"2600"},{"price":"0.86","size":"2600"},{"price":"0.82","size":"999"},{"price":"0.81","size":"999"},{"price":"0.8","size":"250"},{"price":"0.74","size":"999"},{"price":"0.73","size":"999"},{"price":"0.7","size":"120"},{"price":"0.66","size":"999"},{"price":"0.65","size":"999"},{"price":"0.58","size":"2600"},{"price":"0.57","size":"2600"},{"price":"0.55","size":"80"},{"price":"0.45","size":"1029"},{"price":"0.43","size":"999"},{"price":"0.35","size":"1014"},{"price":"0.29","size":"2600"},{"price":"0.27","size":"2610"},{"price":"0.23","size":"999"},{"price":"0.21","size":"999"},{"price":"0.19","size":"5"},{"price":"0.16","size":"999"},{"price":"0.1","size":"44"},{"price":"0.09","size":"1999"},{"price":"0.08","size":"1999"},{"price":"0.05","size":"2005"},{"price":"0.04","size":"2000"},{"price":"0.03","size":"5"},{"price":"0.02","size":"27.6"},{"price":"0.01","size":"284247.23"}],"min_order_size":"5","tick_size":"0.01","neg_risk":false,"last_trade_price":"0.990"}}
{"sample_number":10,"sample_utc":"2026-06-18T18:05:09.6552535+00:00","asset":"SOL","market_slug":"sol-updown-5m-1781805600","outcome":"Down","token_id":"42158671632333916299715271514496933316667556269910783091936524939668698929488","book":{"market":"0x240208a76cd02c37591e0b118ddd74d7caed524a1b0740d840fa5956862c2e6f","asset_id":"42158671632333916299715271514496933316667556269910783091936524939668698929488","timestamp":"1781805907709","hash":"4e006ca72c40fc842d6d236a75a229a610192174","bids":[{"price":"0.01","size":"110423"},{"price":"0.02","size":"1389"},{"price":"0.03","size":"27"},{"price":"0.04","size":"25670"},{"price":"0.05","size":"16"},{"price":"0.06","size":"8000"},{"price":"0.07","size":"480"},{"price":"0.09","size":"999"},{"price":"0.1","size":"999"},{"price":"0.11","size":"2600"},{"price":"0.14","size":"2600"},{"price":"0.18","size":"999"},{"price":"0.19","size":"999"},{"price":"0.2","size":"250"},{"price":"0.26","size":"999"},{"price":"0.27","size":"999"},{"price":"0.3","size":"120"},{"price":"0.34","size":"999"},{"price":"0.35","size":"999"},{"price":"0.42","size":"2600"},{"price":"0.43","size":"2600"},{"price":"0.45","size":"80"},{"price":"0.55","size":"1029"},{"price":"0.57","size":"999"},{"price":"0.65","size":"1014"},{"price":"0.71","size":"2600"},{"price":"0.73","size":"2610"},{"price":"0.77","size":"999"},{"price":"0.79","size":"999"},{"price":"0.81","size":"5"},{"price":"0.84","size":"999"},{"price":"0.9","size":"44"},{"price":"0.91","size":"1999"},{"price":"0.92","size":"1999"},{"price":"0.95","size":"2005"},{"price":"0.96","size":"2000"},{"price":"0.97","size":"5"},{"price":"0.98","size":"27.6"},{"price":"0.99","size":"284247.23"}],"asks":[],"min_order_size":"5","tick_size":"0.01","neg_risk":false,"last_trade_price":"0.990"}}
{"sample_number":10,"sample_utc":"2026-06-18T18:05:09.6552535+00:00","asset":"ETH","market_slug":"eth-updown-5m-1781805600","outcome":"Up","token_id":"54440108909645803563712017609209311553790634574167288046576126967603211899968","book":{"market":"0x5321af2dd99ba82f4abd95b18c702fb05268b58967ad15b3afa0fa94ceb284f1","asset_id":"54440108909645803563712017609209311553790634574167288046576126967603211899968","timestamp":"1781805910775","hash":"bd4b7e3abd1ecab05bf043d07e592c7629793c70","bids":[{"price":"0.01","size":"110698.67"},{"price":"0.02","size":"1774.12"},{"price":"0.03","size":"27"},{"price":"0.04","size":"26320"},{"price":"0.05","size":"90"},{"price":"0.06","size":"8000"},{"price":"0.07","size":"960"},{"price":"0.09","size":"999"},{"price":"0.1","size":"999"},{"price":"0.11","size":"2600"},{"price":"0.14","size":"2600"},{"price":"0.18","size":"999"},{"price":"0.19","size":"999"},{"price":"0.2","size":"500"},{"price":"0.26","size":"999"},{"price":"0.27","size":"999"},{"price":"0.3","size":"240"},{"price":"0.34","size":"999"},{"price":"0.35","size":"999"},{"price":"0.42","size":"2600"},{"price":"0.43","size":"2600"},{"price":"0.45","size":"160"},{"price":"0.55","size":"1059"},{"price":"0.57","size":"999"},{"price":"0.65","size":"1029"},{"price":"0.71","size":"2600"},{"price":"0.73","size":"2600"},{"price":"0.77","size":"999"},{"price":"0.79","size":"999"},{"price":"0.84","size":"999"},{"price":"0.91","size":"1999"},{"price":"0.92","size":"1999"},{"price":"0.95","size":"2000"},{"price":"0.96","size":"2000"},{"price":"0.99","size":"497060.69"}],"asks":[],"min_order_size":"5","tick_size":"0.01","neg_risk":false,"last_trade_price":"0.990"}}
{"sample_number":10,"sample_utc":"2026-06-18T18:05:09.6552535+00:00","asset":"ETH","market_slug":"eth-updown-5m-1781805600","outcome":"Down","token_id":"110358233053529115025378425927539828974870137637838800989881295649187961418248","book":{"market":"0x5321af2dd99ba82f4abd95b18c702fb05268b58967ad15b3afa0fa94ceb284f1","asset_id":"110358233053529115025378425927539828974870137637838800989881295649187961418248","timestamp":"1781805910775","hash":"25df87bea314b67eabb946c8225bd93a8eba0125","bids":[],"asks":[{"price":"0.99","size":"110698.67"},{"price":"0.98","size":"1774.12"},{"price":"0.97","size":"27"},{"price":"0.96","size":"26320"},{"price":"0.95","size":"90"},{"price":"0.94","size":"8000"},{"price":"0.93","size":"960"},{"price":"0.91","size":"999"},{"price":"0.9","size":"999"},{"price":"0.89","size":"2600"},{"price":"0.86","size":"2600"},{"price":"0.82","size":"999"},{"price":"0.81","size":"999"},{"price":"0.8","size":"500"},{"price":"0.74","size":"999"},{"price":"0.73","size":"999"},{"price":"0.7","size":"240"},{"price":"0.66","size":"999"},{"price":"0.65","size":"999"},{"price":"0.58","size":"2600"},{"price":"0.57","size":"2600"},{"price":"0.55","size":"160"},{"price":"0.45","size":"1059"},{"price":"0.43","size":"999"},{"price":"0.35","size":"1029"},{"price":"0.29","size":"2600"},{"price":"0.27","size":"2600"},{"price":"0.23","size":"999"},{"price":"0.21","size":"999"},{"price":"0.16","size":"999"},{"price":"0.09","size":"1999"},{"price":"0.08","size":"1999"},{"price":"0.05","size":"2000"},{"price":"0.04","size":"2000"},{"price":"0.01","size":"497060.69"}],"min_order_size":"5","tick_size":"0.01","neg_risk":false,"last_trade_price":"0.990"}}
{"sample_number":10,"sample_utc":"2026-06-18T18:05:09.6552535+00:00","asset":"BTC","market_slug":"btc-updown-5m-1781805600","outcome":"Up","token_id":"69551560445088382754714827577620718235813378023082728222424940352395440970822","book":{"market":"0xba71c99d7fb34fe556a1fa3203307333821ff8ed1d5297b70313adbdf2ff9b26","asset_id":"69551560445088382754714827577620718235813378023082728222424940352395440970822","timestamp":"1781805911197","hash":"6bc908a80740995b47abd49e4362ea9ae6cf8649","bids":[{"price":"0.01","size":"113651.94"},{"price":"0.02","size":"4280.52"},{"price":"0.03","size":"44"},{"price":"0.04","size":"26823.66"},{"price":"0.05","size":"30185.05"},{"price":"0.06","size":"8036"},{"price":"0.07","size":"1336"},{"price":"0.08","size":"1015.99"},{"price":"0.09","size":"3019"},{"price":"0.1","size":"3046.99"},{"price":"0.11","size":"2605"},{"price":"0.12","size":"7004"},{"price":"0.13","size":"5"},{"price":"0.14","size":"2605"},{"price":"0.15","size":"55"},{"price":"0.16","size":"5"},{"price":"0.17","size":"5"},{"price":"0.18","size":"3013.06"},{"price":"0.19","size":"3004"},{"price":"0.2","size":"702"},{"price":"0.21","size":"3004"},{"price":"0.23","size":"5.18"},{"price":"0.24","size":"3004"},{"price":"0.26","size":"1999"},{"price":"0.27","size":"2004"},{"price":"0.3","size":"336"},{"price":"0.31","size":"2999"},{"price":"0.34","size":"1999"},{"price":"0.35","size":"1999"},{"price":"0.42","size":"2600"},{"price":"0.43","size":"2600"},{"price":"0.45","size":"220"},{"price":"0.51","size":"2000"},{"price":"0.52","size":"5"},{"price":"0.53","size":"2027.37"},{"price":"0.55","size":"2081"},{"price":"0.57","size":"1999"},{"price":"0.61","size":"1999"},{"price":"0.65","size":"2040"},{"price":"0.68","size":"2004"},{"price":"0.71","size":"2600"},{"price":"0.73","size":"2600"},{"price":"0.75","size":"1600"},{"price":"0.77","size":"1999"},{"price":"0.79","size":"2004"},{"price":"0.81","size":"10"},{"price":"0.84","size":"1999"},{"price":"0.86","size":"10"},{"price":"0.88","size":"11.36"},{"price":"0.89","size":"1999"},{"price":"0.9","size":"400"},{"price":"0.91","size":"1999"},{"price":"0.92","size":"2099"},{"price":"0.93","size":"1615.37"},{"price":"0.95","size":"2048.15"},{"price":"0.96","size":"2000"},{"price":"0.97","size":"10"},{"price":"0.98","size":"1635.05"},{"price":"0.99","size":"701008.57"}],"asks":[],"min_order_size":"5","tick_size":"0.01","neg_risk":false,"last_trade_price":"0.990"}}
{"sample_number":10,"sample_utc":"2026-06-18T18:05:09.6552535+00:00","asset":"BTC","market_slug":"btc-updown-5m-1781805600","outcome":"Down","token_id":"20195300913110956058442138189418940832885706023824964145401620330744384196382","book":{"market":"0xba71c99d7fb34fe556a1fa3203307333821ff8ed1d5297b70313adbdf2ff9b26","asset_id":"20195300913110956058442138189418940832885706023824964145401620330744384196382","timestamp":"1781805911197","hash":"855b961bbfdaa4ba0b3fd8233edcd73cab4dee92","bids":[],"asks":[{"price":"0.99","size":"113651.94"},{"price":"0.98","size":"4280.52"},{"price":"0.97","size":"44"},{"price":"0.96","size":"26823.66"},{"price":"0.95","size":"30185.05"},{"price":"0.94","size":"8036"},{"price":"0.93","size":"1336"},{"price":"0.92","size":"1015.99"},{"price":"0.91","size":"3019"},{"price":"0.9","size":"3046.99"},{"price":"0.89","size":"2605"},{"price":"0.88","size":"7004"},{"price":"0.87","size":"5"},{"price":"0.86","size":"2605"},{"price":"0.85","size":"55"},{"price":"0.84","size":"5"},{"price":"0.83","size":"5"},{"price":"0.82","size":"3013.06"},{"price":"0.81","size":"3004"},{"price":"0.8","size":"702"},{"price":"0.79","size":"3004"},{"price":"0.77","size":"5.18"},{"price":"0.76","size":"3004"},{"price":"0.74","size":"1999"},{"price":"0.73","size":"2004"},{"price":"0.7","size":"336"},{"price":"0.69","size":"2999"},{"price":"0.66","size":"1999"},{"price":"0.65","size":"1999"},{"price":"0.58","size":"2600"},{"price":"0.57","size":"2600"},{"price":"0.55","size":"220"},{"price":"0.49","size":"2000"},{"price":"0.48","size":"5"},{"price":"0.47","size":"2027.37"},{"price":"0.45","size":"2081"},{"price":"0.43","size":"1999"},{"price":"0.39","size":"1999"},{"price":"0.35","size":"2040"},{"price":"0.32","size":"2004"},{"price":"0.29","size":"2600"},{"price":"0.27","size":"2600"},{"price":"0.25","size":"1600"},{"price":"0.23","size":"1999"},{"price":"0.21","size":"2004"},{"price":"0.19","size":"10"},{"price":"0.16","size":"1999"},{"price":"0.14","size":"10"},{"price":"0.12","size":"11.36"},{"price":"0.11","size":"1999"},{"price":"0.1","size":"400"},{"price":"0.09","size":"1999"},{"price":"0.08","size":"2099"},{"price":"0.07","size":"1615.37"},{"price":"0.05","size":"2048.15"},{"price":"0.04","size":"2000"},{"price":"0.03","size":"10"},{"price":"0.02","size":"1635.05"},{"price":"0.01","size":"701008.57"}],"min_order_size":"5","tick_size":"0.01","neg_risk":false,"last_trade_price":"0.990"}}
{"sample_number":11,"sample_utc":"2026-06-18T18:05:43.2230139+00:00","asset":"SOL","market_slug":"sol-updown-5m-1781805600","outcome":"Up","token_id":"92887202688210559890269037787373548518364039356424906092889842946664474809719","book":{"market":"0x240208a76cd02c37591e0b118ddd74d7caed524a1b0740d840fa5956862c2e6f","asset_id":"92887202688210559890269037787373548518364039356424906092889842946664474809719","timestamp":"1781805939290","hash":"2b8ab4a177e2d406e72fb1ef3c06b36bec0ab4a1","bids":[],"asks":[{"price":"0.999","size":"115"},{"price":"0.99","size":"110423"},{"price":"0.98","size":"1389"},{"price":"0.97","size":"27"},{"price":"0.96","size":"25670"},{"price":"0.95","size":"16"},{"price":"0.94","size":"8000"},{"price":"0.93","size":"480"},{"price":"0.91","size":"999"},{"price":"0.9","size":"999"},{"price":"0.89","size":"2600"},{"price":"0.86","size":"2600"},{"price":"0.82","size":"999"},{"price":"0.81","size":"999"},{"price":"0.8","size":"250"},{"price":"0.74","size":"999"},{"price":"0.73","size":"999"},{"price":"0.7","size":"120"},{"price":"0.66","size":"999"},{"price":"0.65","size":"999"},{"price":"0.58","size":"2600"},{"price":"0.57","size":"2600"},{"price":"0.55","size":"80"},{"price":"0.45","size":"1029"},{"price":"0.43","size":"999"},{"price":"0.35","size":"1014"},{"price":"0.29","size":"2600"},{"price":"0.27","size":"2610"},{"price":"0.23","size":"999"},{"price":"0.21","size":"999"},{"price":"0.19","size":"5"},{"price":"0.16","size":"999"},{"price":"0.1","size":"44"},{"price":"0.09","size":"1999"},{"price":"0.08","size":"1999"},{"price":"0.05","size":"2005"},{"price":"0.04","size":"2000"},{"price":"0.03","size":"5"},{"price":"0.02","size":"27.6"},{"price":"0.01","size":"276189.69"},{"price":"0.009","size":"80"},{"price":"0.001","size":"177115.24"}],"min_order_size":"5","tick_size":"0.001","neg_risk":false,"last_trade_price":"0.990"}}
{"sample_number":11,"sample_utc":"2026-06-18T18:05:43.2230139+00:00","asset":"SOL","market_slug":"sol-updown-5m-1781805600","outcome":"Down","token_id":"42158671632333916299715271514496933316667556269910783091936524939668698929488","book":{"market":"0x240208a76cd02c37591e0b118ddd74d7caed524a1b0740d840fa5956862c2e6f","asset_id":"42158671632333916299715271514496933316667556269910783091936524939668698929488","timestamp":"1781805939290","hash":"6e91be4681009515e49497c028a721f5d038d6c6","bids":[{"price":"0.001","size":"115"},{"price":"0.01","size":"110423"},{"price":"0.02","size":"1389"},{"price":"0.03","size":"27"},{"price":"0.04","size":"25670"},{"price":"0.05","size":"16"},{"price":"0.06","size":"8000"},{"price":"0.07","size":"480"},{"price":"0.09","size":"999"},{"price":"0.1","size":"999"},{"price":"0.11","size":"2600"},{"price":"0.14","size":"2600"},{"price":"0.18","size":"999"},{"price":"0.19","size":"999"},{"price":"0.2","size":"250"},{"price":"0.26","size":"999"},{"price":"0.27","size":"999"},{"price":"0.3","size":"120"},{"price":"0.34","size":"999"},{"price":"0.35","size":"999"},{"price":"0.42","size":"2600"},{"price":"0.43","size":"2600"},{"price":"0.45","size":"80"},{"price":"0.55","size":"1029"},{"price":"0.57","size":"999"},{"price":"0.65","size":"1014"},{"price":"0.71","size":"2600"},{"price":"0.73","size":"2610"},{"price":"0.77","size":"999"},{"price":"0.79","size":"999"},{"price":"0.81","size":"5"},{"price":"0.84","size":"999"},{"price":"0.9","size":"44"},{"price":"0.91","size":"1999"},{"price":"0.92","size":"1999"},{"price":"0.95","size":"2005"},{"price":"0.96","size":"2000"},{"price":"0.97","size":"5"},{"price":"0.98","size":"27.6"},{"price":"0.99","size":"276189.69"},{"price":"0.991","size":"80"},{"price":"0.999","size":"177115.24"}],"asks":[],"min_order_size":"5","tick_size":"0.001","neg_risk":false,"last_trade_price":"0.990"}}
{"sample_number":11,"sample_utc":"2026-06-18T18:05:43.2230139+00:00","asset":"ETH","market_slug":"eth-updown-5m-1781805600","outcome":"Up","token_id":"54440108909645803563712017609209311553790634574167288046576126967603211899968","book":{"market":"0x5321af2dd99ba82f4abd95b18c702fb05268b58967ad15b3afa0fa94ceb284f1","asset_id":"54440108909645803563712017609209311553790634574167288046576126967603211899968","timestamp":"1781805930490","hash":"e3c8e99b875d0b562f811bb6642fd374f9878ddb","bids":[{"price":"0.01","size":"110698.67"},{"price":"0.02","size":"1774.12"},{"price":"0.03","size":"27"},{"price":"0.04","size":"26320"},{"price":"0.05","size":"90"},{"price":"0.06","size":"8000"},{"price":"0.07","size":"960"},{"price":"0.09","size":"999"},{"price":"0.1","size":"999"},{"price":"0.11","size":"2600"},{"price":"0.14","size":"2600"},{"price":"0.18","size":"999"},{"price":"0.19","size":"999"},{"price":"0.2","size":"500"},{"price":"0.26","size":"999"},{"price":"0.27","size":"999"},{"price":"0.3","size":"240"},{"price":"0.34","size":"999"},{"price":"0.35","size":"999"},{"price":"0.42","size":"2600"},{"price":"0.43","size":"2600"},{"price":"0.45","size":"160"},{"price":"0.55","size":"1059"},{"price":"0.57","size":"999"},{"price":"0.65","size":"1029"},{"price":"0.71","size":"2600"},{"price":"0.73","size":"2600"},{"price":"0.77","size":"999"},{"price":"0.79","size":"999"},{"price":"0.84","size":"999"},{"price":"0.91","size":"1999"},{"price":"0.92","size":"1999"},{"price":"0.95","size":"2000"},{"price":"0.96","size":"2000"},{"price":"0.99","size":"490118.36"}],"asks":[],"min_order_size":"5","tick_size":"0.01","neg_risk":false,"last_trade_price":"0.990"}}
{"sample_number":11,"sample_utc":"2026-06-18T18:05:43.2230139+00:00","asset":"ETH","market_slug":"eth-updown-5m-1781805600","outcome":"Down","token_id":"110358233053529115025378425927539828974870137637838800989881295649187961418248","book":{"market":"0x5321af2dd99ba82f4abd95b18c702fb05268b58967ad15b3afa0fa94ceb284f1","asset_id":"110358233053529115025378425927539828974870137637838800989881295649187961418248","timestamp":"1781805930490","hash":"7101bb0f4deafe7cc69e1761ed57ad713f6fd8d0","bids":[],"asks":[{"price":"0.99","size":"110698.67"},{"price":"0.98","size":"1774.12"},{"price":"0.97","size":"27"},{"price":"0.96","size":"26320"},{"price":"0.95","size":"90"},{"price":"0.94","size":"8000"},{"price":"0.93","size":"960"},{"price":"0.91","size":"999"},{"price":"0.9","size":"999"},{"price":"0.89","size":"2600"},{"price":"0.86","size":"2600"},{"price":"0.82","size":"999"},{"price":"0.81","size":"999"},{"price":"0.8","size":"500"},{"price":"0.74","size":"999"},{"price":"0.73","size":"999"},{"price":"0.7","size":"240"},{"price":"0.66","size":"999"},{"price":"0.65","size":"999"},{"price":"0.58","size":"2600"},{"price":"0.57","size":"2600"},{"price":"0.55","size":"160"},{"price":"0.45","size":"1059"},{"price":"0.43","size":"999"},{"price":"0.35","size":"1029"},{"price":"0.29","size":"2600"},{"price":"0.27","size":"2600"},{"price":"0.23","size":"999"},{"price":"0.21","size":"999"},{"price":"0.16","size":"999"},{"price":"0.09","size":"1999"},{"price":"0.08","size":"1999"},{"price":"0.05","size":"2000"},{"price":"0.04","size":"2000"},{"price":"0.01","size":"490118.36"}],"min_order_size":"5","tick_size":"0.01","neg_risk":false,"last_trade_price":"0.990"}}
{"sample_number":11,"sample_utc":"2026-06-18T18:05:43.2230139+00:00","asset":"BTC","market_slug":"btc-updown-5m-1781805600","outcome":"Up","token_id":"69551560445088382754714827577620718235813378023082728222424940352395440970822","book":{"market":"0xba71c99d7fb34fe556a1fa3203307333821ff8ed1d5297b70313adbdf2ff9b26","asset_id":"69551560445088382754714827577620718235813378023082728222424940352395440970822","timestamp":"1781805940111","hash":"7e122a11378f5ac5e7d9de8a7ccf9e792039ccb3","bids":[{"price":"0.01","size":"113201.95"},{"price":"0.02","size":"4213.52"},{"price":"0.03","size":"44"},{"price":"0.04","size":"26823.66"},{"price":"0.05","size":"30185.05"},{"price":"0.06","size":"8036"},{"price":"0.07","size":"1336"},{"price":"0.08","size":"1015.99"},{"price":"0.09","size":"3019"},{"price":"0.1","size":"3046.99"},{"price":"0.11","size":"2605"},{"price":"0.12","size":"7004"},{"price":"0.13","size":"5"},{"price":"0.14","size":"2605"},{"price":"0.15","size":"55"},{"price":"0.16","size":"5"},{"price":"0.17","size":"5"},{"price":"0.18","size":"3013.06"},{"price":"0.19","size":"3004"},{"price":"0.2","size":"702"},{"price":"0.21","size":"3004"},{"price":"0.23","size":"5.18"},{"price":"0.24","size":"3004"},{"price":"0.26","size":"1999"},{"price":"0.27","size":"2004"},{"price":"0.3","size":"336"},{"price":"0.31","size":"2999"},{"price":"0.34","size":"1999"},{"price":"0.35","size":"2039"},{"price":"0.42","size":"2600"},{"price":"0.43","size":"2600"},{"price":"0.45","size":"220"},{"price":"0.51","size":"2000"},{"price":"0.52","size":"5"},{"price":"0.53","size":"2027.37"},{"price":"0.55","size":"2081"},{"price":"0.57","size":"1999"},{"price":"0.61","size":"1999"},{"price":"0.65","size":"2040"},{"price":"0.68","size":"2004"},{"price":"0.71","size":"2600"},{"price":"0.73","size":"2600"},{"price":"0.75","size":"1600"},{"price":"0.77","size":"1999"},{"price":"0.79","size":"2004"},{"price":"0.84","size":"1999"},{"price":"0.86","size":"10"},{"price":"0.88","size":"11.36"},{"price":"0.89","size":"1999"},{"price":"0.9","size":"400"},{"price":"0.91","size":"1999"},{"price":"0.92","size":"1999"},{"price":"0.93","size":"1615.37"},{"price":"0.95","size":"2022.89"},{"price":"0.96","size":"2000"},{"price":"0.97","size":"10"},{"price":"0.98","size":"1635.05"},{"price":"0.99","size":"674694.16"}],"asks":[],"min_order_size":"5","tick_size":"0.01","neg_risk":false,"last_trade_price":"0.990"}}
{"sample_number":11,"sample_utc":"2026-06-18T18:05:43.2230139+00:00","asset":"BTC","market_slug":"btc-updown-5m-1781805600","outcome":"Down","token_id":"20195300913110956058442138189418940832885706023824964145401620330744384196382","book":{"market":"0xba71c99d7fb34fe556a1fa3203307333821ff8ed1d5297b70313adbdf2ff9b26","asset_id":"20195300913110956058442138189418940832885706023824964145401620330744384196382","timestamp":"1781805940111","hash":"0e6185a67ce6f400ead8577af0f45e121c6880d7","bids":[],"asks":[{"price":"0.99","size":"113201.95"},{"price":"0.98","size":"4213.52"},{"price":"0.97","size":"44"},{"price":"0.96","size":"26823.66"},{"price":"0.95","size":"30185.05"},{"price":"0.94","size":"8036"},{"price":"0.93","size":"1336"},{"price":"0.92","size":"1015.99"},{"price":"0.91","size":"3019"},{"price":"0.9","size":"3046.99"},{"price":"0.89","size":"2605"},{"price":"0.88","size":"7004"},{"price":"0.87","size":"5"},{"price":"0.86","size":"2605"},{"price":"0.85","size":"55"},{"price":"0.84","size":"5"},{"price":"0.83","size":"5"},{"price":"0.82","size":"3013.06"},{"price":"0.81","size":"3004"},{"price":"0.8","size":"702"},{"price":"0.79","size":"3004"},{"price":"0.77","size":"5.18"},{"price":"0.76","size":"3004"},{"price":"0.74","size":"1999"},{"price":"0.73","size":"2004"},{"price":"0.7","size":"336"},{"price":"0.69","size":"2999"},{"price":"0.66","size":"1999"},{"price":"0.65","size":"2039"},{"price":"0.58","size":"2600"},{"price":"0.57","size":"2600"},{"price":"0.55","size":"220"},{"price":"0.49","size":"2000"},{"price":"0.48","size":"5"},{"price":"0.47","size":"2027.37"},{"price":"0.45","size":"2081"},{"price":"0.43","size":"1999"},{"price":"0.39","size":"1999"},{"price":"0.35","size":"2040"},{"price":"0.32","size":"2004"},{"price":"0.29","size":"2600"},{"price":"0.27","size":"2600"},{"price":"0.25","size":"1600"},{"price":"0.23","size":"1999"},{"price":"0.21","size":"2004"},{"price":"0.16","size":"1999"},{"price":"0.14","size":"10"},{"price":"0.12","size":"11.36"},{"price":"0.11","size":"1999"},{"price":"0.1","size":"400"},{"price":"0.09","size":"1999"},{"price":"0.08","size":"1999"},{"price":"0.07","size":"1615.37"},{"price":"0.05","size":"2022.89"},{"price":"0.04","size":"2000"},{"price":"0.03","size":"10"},{"price":"0.02","size":"1635.05"},{"price":"0.01","size":"674694.16"}],"min_order_size":"5","tick_size":"0.01","neg_risk":false,"last_trade_price":"0.990"}}
{"sample_number":12,"sample_utc":"2026-06-18T18:06:16.8950649+00:00","asset":"SOL","market_slug":"sol-updown-5m-1781805600","outcome":"Up","token_id":"92887202688210559890269037787373548518364039356424906092889842946664474809719","book":{"market":"0x240208a76cd02c37591e0b118ddd74d7caed524a1b0740d840fa5956862c2e6f","asset_id":"92887202688210559890269037787373548518364039356424906092889842946664474809719","timestamp":"1781805976000","hash":"fc7eaea4daaaaeff77e7819a5f91d7071cfa320e","bids":[],"asks":[{"price":"0.999","size":"115"},{"price":"0.99","size":"110423"},{"price":"0.98","size":"1389"},{"price":"0.97","size":"27"},{"price":"0.96","size":"25670"},{"price":"0.95","size":"16"},{"price":"0.94","size":"8000"},{"price":"0.93","size":"480"},{"price":"0.91","size":"999"},{"price":"0.9","size":"999"},{"price":"0.89","size":"2600"},{"price":"0.86","size":"2600"},{"price":"0.82","size":"999"},{"price":"0.81","size":"999"},{"price":"0.8","size":"250"},{"price":"0.74","size":"999"},{"price":"0.73","size":"999"},{"price":"0.7","size":"120"},{"price":"0.66","size":"999"},{"price":"0.65","size":"999"},{"price":"0.58","size":"2600"},{"price":"0.57","size":"2600"},{"price":"0.55","size":"80"},{"price":"0.45","size":"1029"},{"price":"0.43","size":"999"},{"price":"0.35","size":"1014"},{"price":"0.29","size":"2600"},{"price":"0.27","size":"2610"},{"price":"0.23","size":"999"},{"price":"0.21","size":"999"},{"price":"0.19","size":"5"},{"price":"0.16","size":"999"},{"price":"0.1","size":"44"},{"price":"0.09","size":"1999"},{"price":"0.08","size":"1999"},{"price":"0.05","size":"2005"},{"price":"0.04","size":"2000"},{"price":"0.03","size":"5"},{"price":"0.02","size":"27.6"},{"price":"0.01","size":"276154.59"},{"price":"0.009","size":"80"},{"price":"0.001","size":"177115.24"}],"min_order_size":"5","tick_size":"0.001","neg_risk":false,"last_trade_price":"0.990"}}
{"sample_number":12,"sample_utc":"2026-06-18T18:06:16.8950649+00:00","asset":"SOL","market_slug":"sol-updown-5m-1781805600","outcome":"Down","token_id":"42158671632333916299715271514496933316667556269910783091936524939668698929488","book":{"market":"0x240208a76cd02c37591e0b118ddd74d7caed524a1b0740d840fa5956862c2e6f","asset_id":"42158671632333916299715271514496933316667556269910783091936524939668698929488","timestamp":"1781805976000","hash":"e4491e44784fc54dc9605e9ff7b4e7a04a610ad2","bids":[{"price":"0.001","size":"115"},{"price":"0.01","size":"110423"},{"price":"0.02","size":"1389"},{"price":"0.03","size":"27"},{"price":"0.04","size":"25670"},{"price":"0.05","size":"16"},{"price":"0.06","size":"8000"},{"price":"0.07","size":"480"},{"price":"0.09","size":"999"},{"price":"0.1","size":"999"},{"price":"0.11","size":"2600"},{"price":"0.14","size":"2600"},{"price":"0.18","size":"999"},{"price":"0.19","size":"999"},{"price":"0.2","size":"250"},{"price":"0.26","size":"999"},{"price":"0.27","size":"999"},{"price":"0.3","size":"120"},{"price":"0.34","size":"999"},{"price":"0.35","size":"999"},{"price":"0.42","size":"2600"},{"price":"0.43","size":"2600"},{"price":"0.45","size":"80"},{"price":"0.55","size":"1029"},{"price":"0.57","size":"999"},{"price":"0.65","size":"1014"},{"price":"0.71","size":"2600"},{"price":"0.73","size":"2610"},{"price":"0.77","size":"999"},{"price":"0.79","size":"999"},{"price":"0.81","size":"5"},{"price":"0.84","size":"999"},{"price":"0.9","size":"44"},{"price":"0.91","size":"1999"},{"price":"0.92","size":"1999"},{"price":"0.95","size":"2005"},{"price":"0.96","size":"2000"},{"price":"0.97","size":"5"},{"price":"0.98","size":"27.6"},{"price":"0.99","size":"276154.59"},{"price":"0.991","size":"80"},{"price":"0.999","size":"177115.24"}],"asks":[],"min_order_size":"5","tick_size":"0.001","neg_risk":false,"last_trade_price":"0.990"}}
{"sample_number":12,"sample_utc":"2026-06-18T18:06:16.8950649+00:00","asset":"ETH","market_slug":"eth-updown-5m-1781805600","outcome":"Up","token_id":"54440108909645803563712017609209311553790634574167288046576126967603211899968","book":{"market":"0x5321af2dd99ba82f4abd95b18c702fb05268b58967ad15b3afa0fa94ceb284f1","asset_id":"54440108909645803563712017609209311553790634574167288046576126967603211899968","timestamp":"1781805960279","hash":"f2e9b9c801dc5cb2990fd21e919974509c97e8bc","bids":[{"price":"0.01","size":"110693.67"},{"price":"0.02","size":"1774.12"},{"price":"0.03","size":"27"},{"price":"0.04","size":"26320"},{"price":"0.05","size":"90"},{"price":"0.06","size":"8000"},{"price":"0.07","size":"960"},{"price":"0.09","size":"999"},{"price":"0.1","size":"999"},{"price":"0.11","size":"2600"},{"price":"0.14","size":"2600"},{"price":"0.18","size":"999"},{"price":"0.19","size":"999"},{"price":"0.2","size":"500"},{"price":"0.26","size":"999"},{"price":"0.27","size":"999"},{"price":"0.3","size":"240"},{"price":"0.34","size":"999"},{"price":"0.35","size":"999"},{"price":"0.42","size":"2600"},{"price":"0.43","size":"2600"},{"price":"0.45","size":"160"},{"price":"0.55","size":"1059"},{"price":"0.57","size":"999"},{"price":"0.65","size":"1029"},{"price":"0.71","size":"2600"},{"price":"0.73","size":"2600"},{"price":"0.77","size":"999"},{"price":"0.79","size":"999"},{"price":"0.84","size":"999"},{"price":"0.91","size":"1999"},{"price":"0.92","size":"1999"},{"price":"0.95","size":"2000"},{"price":"0.96","size":"2000"},{"price":"0.99","size":"489923.36"}],"asks":[],"min_order_size":"5","tick_size":"0.01","neg_risk":false,"last_trade_price":"0.990"}}
{"sample_number":12,"sample_utc":"2026-06-18T18:06:16.8950649+00:00","asset":"ETH","market_slug":"eth-updown-5m-1781805600","outcome":"Down","token_id":"110358233053529115025378425927539828974870137637838800989881295649187961418248","book":{"market":"0x5321af2dd99ba82f4abd95b18c702fb05268b58967ad15b3afa0fa94ceb284f1","asset_id":"110358233053529115025378425927539828974870137637838800989881295649187961418248","timestamp":"1781805960279","hash":"05193e7c2449ee9cf065a4a2896f13d386b53705","bids":[],"asks":[{"price":"0.99","size":"110693.67"},{"price":"0.98","size":"1774.12"},{"price":"0.97","size":"27"},{"price":"0.96","size":"26320"},{"price":"0.95","size":"90"},{"price":"0.94","size":"8000"},{"price":"0.93","size":"960"},{"price":"0.91","size":"999"},{"price":"0.9","size":"999"},{"price":"0.89","size":"2600"},{"price":"0.86","size":"2600"},{"price":"0.82","size":"999"},{"price":"0.81","size":"999"},{"price":"0.8","size":"500"},{"price":"0.74","size":"999"},{"price":"0.73","size":"999"},{"price":"0.7","size":"240"},{"price":"0.66","size":"999"},{"price":"0.65","size":"999"},{"price":"0.58","size":"2600"},{"price":"0.57","size":"2600"},{"price":"0.55","size":"160"},{"price":"0.45","size":"1059"},{"price":"0.43","size":"999"},{"price":"0.35","size":"1029"},{"price":"0.29","size":"2600"},{"price":"0.27","size":"2600"},{"price":"0.23","size":"999"},{"price":"0.21","size":"999"},{"price":"0.16","size":"999"},{"price":"0.09","size":"1999"},{"price":"0.08","size":"1999"},{"price":"0.05","size":"2000"},{"price":"0.04","size":"2000"},{"price":"0.01","size":"489923.36"}],"min_order_size":"5","tick_size":"0.01","neg_risk":false,"last_trade_price":"0.990"}}
{"sample_number":12,"sample_utc":"2026-06-18T18:06:16.8950649+00:00","asset":"BTC","market_slug":"btc-updown-5m-1781805600","outcome":"Up","token_id":"69551560445088382754714827577620718235813378023082728222424940352395440970822","book":{"market":"0xba71c99d7fb34fe556a1fa3203307333821ff8ed1d5297b70313adbdf2ff9b26","asset_id":"69551560445088382754714827577620718235813378023082728222424940352395440970822","timestamp":"1781805970224","hash":"16cf324e20207e5109fe5ba0e4d998f5080a120c","bids":[{"price":"0.01","size":"113201.95"},{"price":"0.02","size":"4213.52"},{"price":"0.03","size":"44"},{"price":"0.04","size":"26823.66"},{"price":"0.05","size":"30185.05"},{"price":"0.06","size":"8036"},{"price":"0.07","size":"1336"},{"price":"0.08","size":"1015.99"},{"price":"0.09","size":"3019"},{"price":"0.1","size":"3046.99"},{"price":"0.11","size":"2605"},{"price":"0.12","size":"7004"},{"price":"0.13","size":"5"},{"price":"0.14","size":"2605"},{"price":"0.15","size":"55"},{"price":"0.16","size":"5"},{"price":"0.17","size":"5"},{"price":"0.18","size":"3013.06"},{"price":"0.19","size":"3004"},{"price":"0.2","size":"702"},{"price":"0.21","size":"3004"},{"price":"0.23","size":"5.18"},{"price":"0.24","size":"3004"},{"price":"0.26","size":"1999"},{"price":"0.27","size":"2004"},{"price":"0.3","size":"336"},{"price":"0.31","size":"2999"},{"price":"0.34","size":"1999"},{"price":"0.35","size":"2039"},{"price":"0.42","size":"2600"},{"price":"0.43","size":"2600"},{"price":"0.45","size":"220"},{"price":"0.5","size":"5"},{"price":"0.51","size":"2000"},{"price":"0.52","size":"5"},{"price":"0.53","size":"2027.37"},{"price":"0.55","size":"2081"},{"price":"0.57","size":"1999"},{"price":"0.61","size":"1999"},{"price":"0.65","size":"2040"},{"price":"0.68","size":"2004"},{"price":"0.71","size":"2600"},{"price":"0.73","size":"2600"},{"price":"0.75","size":"1600"},{"price":"0.77","size":"1999"},{"price":"0.79","size":"2004"},{"price":"0.84","size":"1999"},{"price":"0.86","size":"10"},{"price":"0.88","size":"11.36"},{"price":"0.89","size":"1999"},{"price":"0.9","size":"400"},{"price":"0.91","size":"1999"},{"price":"0.92","size":"1999"},{"price":"0.93","size":"1615.37"},{"price":"0.95","size":"2022.89"},{"price":"0.96","size":"2000"},{"price":"0.97","size":"10"},{"price":"0.98","size":"1635.05"},{"price":"0.99","size":"674558.23"}],"asks":[],"min_order_size":"5","tick_size":"0.01","neg_risk":false,"last_trade_price":"0.990"}}
{"sample_number":12,"sample_utc":"2026-06-18T18:06:16.8950649+00:00","asset":"BTC","market_slug":"btc-updown-5m-1781805600","outcome":"Down","token_id":"20195300913110956058442138189418940832885706023824964145401620330744384196382","book":{"market":"0xba71c99d7fb34fe556a1fa3203307333821ff8ed1d5297b70313adbdf2ff9b26","asset_id":"20195300913110956058442138189418940832885706023824964145401620330744384196382","timestamp":"1781805970224","hash":"a356eae7332af5ff741500ee036338475c1bf7ea","bids":[],"asks":[{"price":"0.99","size":"113201.95"},{"price":"0.98","size":"4213.52"},{"price":"0.97","size":"44"},{"price":"0.96","size":"26823.66"},{"price":"0.95","size":"30185.05"},{"price":"0.94","size":"8036"},{"price":"0.93","size":"1336"},{"price":"0.92","size":"1015.99"},{"price":"0.91","size":"3019"},{"price":"0.9","size":"3046.99"},{"price":"0.89","size":"2605"},{"price":"0.88","size":"7004"},{"price":"0.87","size":"5"},{"price":"0.86","size":"2605"},{"price":"0.85","size":"55"},{"price":"0.84","size":"5"},{"price":"0.83","size":"5"},{"price":"0.82","size":"3013.06"},{"price":"0.81","size":"3004"},{"price":"0.8","size":"702"},{"price":"0.79","size":"3004"},{"price":"0.77","size":"5.18"},{"price":"0.76","size":"3004"},{"price":"0.74","size":"1999"},{"price":"0.73","size":"2004"},{"price":"0.7","size":"336"},{"price":"0.69","size":"2999"},{"price":"0.66","size":"1999"},{"price":"0.65","size":"2039"},{"price":"0.58","size":"2600"},{"price":"0.57","size":"2600"},{"price":"0.55","size":"220"},{"price":"0.5","size":"5"},{"price":"0.49","size":"2000"},{"price":"0.48","size":"5"},{"price":"0.47","size":"2027.37"},{"price":"0.45","size":"2081"},{"price":"0.43","size":"1999"},{"price":"0.39","size":"1999"},{"price":"0.35","size":"2040"},{"price":"0.32","size":"2004"},{"price":"0.29","size":"2600"},{"price":"0.27","size":"2600"},{"price":"0.25","size":"1600"},{"price":"0.23","size":"1999"},{"price":"0.21","size":"2004"},{"price":"0.16","size":"1999"},{"price":"0.14","size":"10"},{"price":"0.12","size":"11.36"},{"price":"0.11","size":"1999"},{"price":"0.1","size":"400"},{"price":"0.09","size":"1999"},{"price":"0.08","size":"1999"},{"price":"0.07","size":"1615.37"},{"price":"0.05","size":"2022.89"},{"price":"0.04","size":"2000"},{"price":"0.03","size":"10"},{"price":"0.02","size":"1635.05"},{"price":"0.01","size":"674558.23"}],"min_order_size":"5","tick_size":"0.01","neg_risk":false,"last_trade_price":"0.990"}}
{"sample_number":18,"sample_utc":"2026-06-18T18:09:35.2631079+00:00","asset":"BTC","market_slug":"btc-updown-5m-1781805900","outcome":"Up","token_id":"84992519852971935377829666695110129200269350761576584997248599646134881919776","book":{"market":"0x8506535a52f6b682f53f20d77739545978544028b27e4ab3c2609a3b21b32096","asset_id":"84992519852971935377829666695110129200269350761576584997248599646134881919776","timestamp":"1781806176925","hash":"3a4d277de364db12b4737f45a01f643ceb7d6f6e","bids":[{"price":"0.01","size":"10686.54"},{"price":"0.02","size":"2080.51"},{"price":"0.03","size":"903.61"},{"price":"0.04","size":"669.65"},{"price":"0.05","size":"1009.4"},{"price":"0.06","size":"462"},{"price":"0.07","size":"636"},{"price":"0.08","size":"131.7"},{"price":"0.09","size":"153.9"},{"price":"0.1","size":"500.4"},{"price":"0.11","size":"380.11"},{"price":"0.12","size":"235.3"},{"price":"0.13","size":"283.5"},{"price":"0.14","size":"232.8"},{"price":"0.15","size":"449.52"},{"price":"0.16","size":"355.69"},{"price":"0.17","size":"303.19"},{"price":"0.18","size":"228.8"},{"price":"0.19","size":"278.4"},{"price":"0.2","size":"247.1"},{"price":"0.21","size":"372.03"},{"price":"0.22","size":"226.6"},{"price":"0.23","size":"276.3"},{"price":"0.24","size":"226.1"},{"price":"0.25","size":"285.9"},{"price":"0.26","size":"225.8"},{"price":"0.27","size":"275.6"},{"price":"0.28","size":"225.4"},{"price":"0.29","size":"275.3"},{"price":"0.3","size":"260.65"},{"price":"0.31","size":"339.61"},{"price":"0.32","size":"225"},{"price":"0.33","size":"274.9"},{"price":"0.34","size":"224.8"},{"price":"0.35","size":"334.67"},{"price":"0.36","size":"219.6"},{"price":"0.37","size":"269.6"},{"price":"0.38","size":"226.69"},{"price":"0.39","size":"269.5"},{"price":"0.4","size":"234.4"},{"price":"0.41","size":"343.18"},{"price":"0.42","size":"219.3"},{"price":"0.43","size":"269.3"},{"price":"0.44","size":"223.66"},{"price":"0.45","size":"429.3"},{"price":"0.46","size":"219.2"},{"price":"0.47","size":"269.2"},{"price":"0.48","size":"219.2"},{"price":"0.49","size":"274.2"},{"price":"0.5","size":"260.73"},{"price":"0.51","size":"762.61"},{"price":"0.52","size":"229.2"},{"price":"0.53","size":"269.2"},{"price":"0.54","size":"224.2"},{"price":"0.55","size":"280.3"},{"price":"0.56","size":"219.3"},{"price":"0.57","size":"269.3"},{"price":"0.58","size":"436.89"},{"price":"0.59","size":"269.4"},{"price":"0.6","size":"325.02"},{"price":"0.61","size":"172.9"},{"price":"0.62","size":"229.5"},{"price":"0.63","size":"269.6"},{"price":"0.64","size":"219.6"},{"price":"0.65","size":"269.7"},{"price":"0.66","size":"219.8"},{"price":"0.67","size":"284.9"},{"price":"0.68","size":"225"},{"price":"0.69","size":"289.6"},{"price":"0.7","size":"241.93"},{"price":"0.71","size":"280.3"},{"price":"0.72","size":"237.4"},{"price":"0.73","size":"880.6"},{"price":"0.74","size":"127.8"},{"price":"0.75","size":"520.88"},{"price":"0.76","size":"221.1"},{"price":"0.77","size":"271.3"},{"price":"0.78","size":"221.6"},{"price":"0.79","size":"280.8"},{"price":"0.8","size":"342.1"},{"price":"0.81","size":"272.4"},{"price":"0.82","size":"237.8"},{"price":"0.83","size":"273.19"},{"price":"0.84","size":"233.69"},{"price":"0.85","size":"290.91"},{"price":"0.86","size":"116.8"},{"price":"0.87","size":"275.5"},{"price":"0.88","size":"221.3"},{"price":"0.89","size":"277.3"},{"price":"0.9","size":"258.94"},{"price":"0.91","size":"279"},{"price":"0.92","size":"337"},{"price":"0.93","size":"682.75"},{"price":"0.94","size":"514"},{"price":"0.95","size":"574"},{"price":"0.96","size":"190.59"},{"price":"0.97","size":"256.43"},{"price":"0.98","size":"366.1"},{"price":"0.99","size":"1836.85"}],"asks":[],"min_order_size":"5","tick_size":"0.01","neg_risk":false,"last_trade_price":"0.990"}}
{"sample_number":18,"sample_utc":"2026-06-18T18:09:35.2631079+00:00","asset":"BTC","market_slug":"btc-updown-5m-1781805900","outcome":"Down","token_id":"42465430903139473100546293101713411666359504294071645838614940811631751292310","book":{"market":"0x8506535a52f6b682f53f20d77739545978544028b27e4ab3c2609a3b21b32096","asset_id":"42465430903139473100546293101713411666359504294071645838614940811631751292310","timestamp":"1781806177041","hash":"685b0d51cde503eee8efa8dcf386f985e9af7a89","bids":[],"asks":[{"price":"0.99","size":"11171.54"},{"price":"0.98","size":"2080.51"},{"price":"0.97","size":"908.61"},{"price":"0.96","size":"669.65"},{"price":"0.95","size":"1009.4"},{"price":"0.94","size":"462"},{"price":"0.93","size":"636"},{"price":"0.92","size":"131.7"},{"price":"0.91","size":"153.9"},{"price":"0.9","size":"500.4"},{"price":"0.89","size":"380.11"},{"price":"0.88","size":"235.3"},{"price":"0.87","size":"283.5"},{"price":"0.86","size":"232.8"},{"price":"0.85","size":"449.52"},{"price":"0.84","size":"355.69"},{"price":"0.83","size":"303.19"},{"price":"0.82","size":"228.8"},{"price":"0.81","size":"278.4"},{"price":"0.8","size":"247.1"},{"price":"0.79","size":"372.03"},{"price":"0.78","size":"226.6"},{"price":"0.77","size":"276.3"},{"price":"0.76","size":"226.1"},{"price":"0.75","size":"285.9"},{"price":"0.74","size":"225.8"},{"price":"0.73","size":"275.6"},{"price":"0.72","size":"225.4"},{"price":"0.71","size":"275.3"},{"price":"0.7","size":"260.65"},{"price":"0.69","size":"339.61"},{"price":"0.68","size":"225"},{"price":"0.67","size":"274.9"},{"price":"0.66","size":"224.8"},{"price":"0.65","size":"334.67"},{"price":"0.64","size":"219.6"},{"price":"0.63","size":"269.6"},{"price":"0.62","size":"226.69"},{"price":"0.61","size":"269.5"},{"price":"0.6","size":"234.4"},{"price":"0.59","size":"343.18"},{"price":"0.58","size":"219.3"},{"price":"0.57","size":"269.3"},{"price":"0.56","size":"223.66"},{"price":"0.55","size":"429.3"},{"price":"0.54","size":"219.2"},{"price":"0.53","size":"269.2"},{"price":"0.52","size":"219.2"},{"price":"0.51","size":"274.2"},{"price":"0.5","size":"260.73"},{"price":"0.49","size":"762.61"},{"price":"0.48","size":"229.2"},{"price":"0.47","size":"269.2"},{"price":"0.46","size":"224.2"},{"price":"0.45","size":"280.3"},{"price":"0.44","size":"219.3"},{"price":"0.43","size":"269.3"},{"price":"0.42","size":"436.89"},{"price":"0.41","size":"269.4"},{"price":"0.4","size":"325.02"},{"price":"0.39","size":"172.9"},{"price":"0.38","size":"229.5"},{"price":"0.37","size":"269.6"},{"price":"0.36","size":"219.6"},{"price":"0.35","size":"269.7"},{"price":"0.34","size":"219.8"},{"price":"0.33","size":"284.9"},{"price":"0.32","size":"225"},{"price":"0.31","size":"289.6"},{"price":"0.3","size":"241.93"},{"price":"0.29","size":"280.3"},{"price":"0.28","size":"237.4"},{"price":"0.27","size":"880.6"},{"price":"0.26","size":"127.8"},{"price":"0.25","size":"520.88"},{"price":"0.24","size":"221.1"},{"price":"0.23","size":"271.3"},{"price":"0.22","size":"221.6"},{"price":"0.21","size":"280.8"},{"price":"0.2","size":"342.1"},{"price":"0.19","size":"272.4"},{"price":"0.18","size":"237.8"},{"price":"0.17","size":"273.19"},{"price":"0.16","size":"233.69"},{"price":"0.15","size":"290.91"},{"price":"0.14","size":"116.8"},{"price":"0.13","size":"275.5"},{"price":"0.12","size":"221.3"},{"price":"0.11","size":"277.3"},{"price":"0.1","size":"258.94"},{"price":"0.09","size":"294.9"},{"price":"0.08","size":"337"},{"price":"0.07","size":"682.75"},{"price":"0.06","size":"514"},{"price":"0.05","size":"574"},{"price":"0.04","size":"190.59"},{"price":"0.03","size":"256.43"},{"price":"0.02","size":"366.1"},{"price":"0.01","size":"1836.85"}],"min_order_size":"5","tick_size":"0.01","neg_risk":false,"last_trade_price":"0.990"}}
{"sample_number":19,"sample_utc":"2026-06-18T18:10:07.9147658+00:00","asset":"ETH","market_slug":"eth-updown-5m-1781805900","outcome":"Up","token_id":"87638470687256180789625872353959436232072330222476306766552913512268745202636","book":{"market":"0xc4848f78d533e55544fdde0ded280ad7ca5126882d67812d9248377570186e23","asset_id":"87638470687256180789625872353959436232072330222476306766552913512268745202636","timestamp":"1781806206945","hash":"39fd5353ca8459dec5fd2223c086ffd77e4740e4","bids":[{"price":"0.01","size":"110697.05"},{"price":"0.02","size":"1739"},{"price":"0.03","size":"27"},{"price":"0.04","size":"26320"},{"price":"0.05","size":"16"},{"price":"0.06","size":"8000"},{"price":"0.07","size":"960"},{"price":"0.09","size":"999"},{"price":"0.1","size":"999"},{"price":"0.11","size":"2600"},{"price":"0.14","size":"2600"},{"price":"0.18","size":"999"},{"price":"0.19","size":"999"},{"price":"0.2","size":"510"},{"price":"0.26","size":"999"},{"price":"0.27","size":"999"},{"price":"0.3","size":"250"},{"price":"0.34","size":"999"},{"price":"0.35","size":"999"},{"price":"0.42","size":"2600"},{"price":"0.43","size":"2600"},{"price":"0.45","size":"170"},{"price":"0.5","size":"11"},{"price":"0.55","size":"1059"},{"price":"0.57","size":"999"},{"price":"0.61","size":"8"},{"price":"0.65","size":"1039"},{"price":"0.71","size":"2600"},{"price":"0.72","size":"5"},{"price":"0.73","size":"2600"},{"price":"0.77","size":"999"},{"price":"0.79","size":"999"},{"price":"0.84","size":"999"},{"price":"0.9","size":"5.4"},{"price":"0.91","size":"1999"},{"price":"0.92","size":"2004.4"},{"price":"0.95","size":"2005"},{"price":"0.96","size":"2000"},{"price":"0.98","size":"52"},{"price":"0.99","size":"376249.62"}],"asks":[],"min_order_size":"5","tick_size":"0.01","neg_risk":false,"last_trade_price":"0.990"}}
{"sample_number":19,"sample_utc":"2026-06-18T18:10:07.9147658+00:00","asset":"ETH","market_slug":"eth-updown-5m-1781805900","outcome":"Down","token_id":"6433665683337383870393395622078943490078528184181542297078329973561292970114","book":{"market":"0xc4848f78d533e55544fdde0ded280ad7ca5126882d67812d9248377570186e23","asset_id":"6433665683337383870393395622078943490078528184181542297078329973561292970114","timestamp":"1781806206945","hash":"eb9a5ea800ce19edacdd02f9c0739fe69b3a81e8","bids":[],"asks":[{"price":"0.99","size":"110697.05"},{"price":"0.98","size":"1739"},{"price":"0.97","size":"27"},{"price":"0.96","size":"26320"},{"price":"0.95","size":"16"},{"price":"0.94","size":"8000"},{"price":"0.93","size":"960"},{"price":"0.91","size":"999"},{"price":"0.9","size":"999"},{"price":"0.89","size":"2600"},{"price":"0.86","size":"2600"},{"price":"0.82","size":"999"},{"price":"0.81","size":"999"},{"price":"0.8","size":"510"},{"price":"0.74","size":"999"},{"price":"0.73","size":"999"},{"price":"0.7","size":"250"},{"price":"0.66","size":"999"},{"price":"0.65","size":"999"},{"price":"0.58","size":"2600"},{"price":"0.57","size":"2600"},{"price":"0.55","size":"170"},{"price":"0.5","size":"11"},{"price":"0.45","size":"1059"},{"price":"0.43","size":"999"},{"price":"0.39","size":"8"},{"price":"0.35","size":"1039"},{"price":"0.29","size":"2600"},{"price":"0.28","size":"5"},{"price":"0.27","size":"2600"},{"price":"0.23","size":"999"},{"price":"0.21","size":"999"},{"price":"0.16","size":"999"},{"price":"0.1","size":"5.4"},{"price":"0.09","size":"1999"},{"price":"0.08","size":"2004.4"},{"price":"0.05","size":"2005"},{"price":"0.04","size":"2000"},{"price":"0.02","size":"52"},{"price":"0.01","size":"376249.62"}],"min_order_size":"5","tick_size":"0.01","neg_risk":false,"last_trade_price":"0.990"}}
{"sample_number":19,"sample_utc":"2026-06-18T18:10:07.9147658+00:00","asset":"BTC","market_slug":"btc-updown-5m-1781805900","outcome":"Up","token_id":"84992519852971935377829666695110129200269350761576584997248599646134881919776","book":{"market":"0x8506535a52f6b682f53f20d77739545978544028b27e4ab3c2609a3b21b32096","asset_id":"84992519852971935377829666695110129200269350761576584997248599646134881919776","timestamp":"1781806208809","hash":"e80a8e6685e3a60bbf1e2229fd8a8207b724cd09","bids":[{"price":"0.01","size":"114043.24"},{"price":"0.02","size":"4391.52"},{"price":"0.03","size":"162.25"},{"price":"0.04","size":"26911.75"},{"price":"0.05","size":"30101"},{"price":"0.06","size":"8036"},{"price":"0.07","size":"1335"},{"price":"0.08","size":"1039"},{"price":"0.09","size":"3009"},{"price":"0.1","size":"3014"},{"price":"0.11","size":"2629"},{"price":"0.12","size":"7004"},{"price":"0.13","size":"5"},{"price":"0.14","size":"2605"},{"price":"0.15","size":"168.33"},{"price":"0.16","size":"5"},{"price":"0.17","size":"29"},{"price":"0.18","size":"3004"},{"price":"0.19","size":"3004"},{"price":"0.2","size":"697"},{"price":"0.21","size":"3004"},{"price":"0.22","size":"5"},{"price":"0.23","size":"5"},{"price":"0.24","size":"3004"},{"price":"0.25","size":"5"},{"price":"0.26","size":"2004"},{"price":"0.27","size":"2004"},{"price":"0.28","size":"5"},{"price":"0.29","size":"5"},{"price":"0.3","size":"360.45"},{"price":"0.31","size":"3004"},{"price":"0.32","size":"5"},{"price":"0.33","size":"5"},{"price":"0.34","size":"2004"},{"price":"0.35","size":"2053.97"},{"price":"0.38","size":"7.19"},{"price":"0.4","size":"10"},{"price":"0.41","size":"25"},{"price":"0.42","size":"2600"},{"price":"0.43","size":"2600"},{"price":"0.44","size":"5"},{"price":"0.45","size":"220"},{"price":"0.49","size":"5"},{"price":"0.5","size":"46.53"},{"price":"0.51","size":"2488.41"},{"price":"0.52","size":"10"},{"price":"0.53","size":"1999"},{"price":"0.54","size":"5"},{"price":"0.55","size":"2086"},{"price":"0.57","size":"1999"},{"price":"0.58","size":"217.59"},{"price":"0.6","size":"105.62"},{"price":"0.61","size":"2015.4"},{"price":"0.62","size":"10"},{"price":"0.65","size":"2040"},{"price":"0.67","size":"15"},{"price":"0.68","size":"2004"},{"price":"0.69","size":"19.5"},{"price":"0.7","size":"21.73"},{"price":"0.71","size":"2605"},{"price":"0.72","size":"17"},{"price":"0.73","size":"2610"},{"price":"0.74","size":"10"},{"price":"0.75","size":"1849.98"},{"price":"0.77","size":"1999"},{"price":"0.79","size":"1999"},{"price":"0.8","size":"120"},{"price":"0.82","size":"15"},{"price":"0.84","size":"1999"},{"price":"0.85","size":"16.72"},{"price":"0.86","size":"10"},{"price":"0.89","size":"1999"},{"price":"0.91","size":"1999"},{"price":"0.92","size":"2610.27"},{"price":"0.93","size":"1600"},{"price":"0.94","size":"5"},{"price":"0.95","size":"2032.89"},{"price":"0.96","size":"2005"},{"price":"0.98","size":"1685.24"},{"price":"0.99","size":"761386.32"}],"asks":[],"min_order_size":"5","tick_size":"0.01","neg_risk":false,"last_trade_price":"0.990"}}
{"sample_number":19,"sample_utc":"2026-06-18T18:10:07.9147658+00:00","asset":"BTC","market_slug":"btc-updown-5m-1781805900","outcome":"Down","token_id":"42465430903139473100546293101713411666359504294071645838614940811631751292310","book":{"market":"0x8506535a52f6b682f53f20d77739545978544028b27e4ab3c2609a3b21b32096","asset_id":"42465430903139473100546293101713411666359504294071645838614940811631751292310","timestamp":"1781806208809","hash":"a78c55aef7c8887eb386ced0afcfc8d7dda8374e","bids":[],"asks":[{"price":"0.99","size":"114043.24"},{"price":"0.98","size":"4391.52"},{"price":"0.97","size":"162.25"},{"price":"0.96","size":"26911.75"},{"price":"0.95","size":"30101"},{"price":"0.94","size":"8036"},{"price":"0.93","size":"1335"},{"price":"0.92","size":"1039"},{"price":"0.91","size":"3009"},{"price":"0.9","size":"3014"},{"price":"0.89","size":"2629"},{"price":"0.88","size":"7004"},{"price":"0.87","size":"5"},{"price":"0.86","size":"2605"},{"price":"0.85","size":"168.33"},{"price":"0.84","size":"5"},{"price":"0.83","size":"29"},{"price":"0.82","size":"3004"},{"price":"0.81","size":"3004"},{"price":"0.8","size":"697"},{"price":"0.79","size":"3004"},{"price":"0.78","size":"5"},{"price":"0.77","size":"5"},{"price":"0.76","size":"3004"},{"price":"0.75","size":"5"},{"price":"0.74","size":"2004"},{"price":"0.73","size":"2004"},{"price":"0.72","size":"5"},{"price":"0.71","size":"5"},{"price":"0.7","size":"360.45"},{"price":"0.69","size":"3004"},{"price":"0.68","size":"5"},{"price":"0.67","size":"5"},{"price":"0.66","size":"2004"},{"price":"0.65","size":"2053.97"},{"price":"0.62","size":"7.19"},{"price":"0.6","size":"10"},{"price":"0.59","size":"25"},{"price":"0.58","size":"2600"},{"price":"0.57","size":"2600"},{"price":"0.56","size":"5"},{"price":"0.55","size":"220"},{"price":"0.51","size":"5"},{"price":"0.5","size":"46.53"},{"price":"0.49","size":"2488.41"},{"price":"0.48","size":"10"},{"price":"0.47","size":"1999"},{"price":"0.46","size":"5"},{"price":"0.45","size":"2086"},{"price":"0.43","size":"1999"},{"price":"0.42","size":"217.59"},{"price":"0.4","size":"105.62"},{"price":"0.39","size":"2015.4"},{"price":"0.38","size":"10"},{"price":"0.35","size":"2040"},{"price":"0.33","size":"15"},{"price":"0.32","size":"2004"},{"price":"0.31","size":"19.5"},{"price":"0.3","size":"21.73"},{"price":"0.29","size":"2605"},{"price":"0.28","size":"17"},{"price":"0.27","size":"2610"},{"price":"0.26","size":"10"},{"price":"0.25","size":"1849.98"},{"price":"0.23","size":"1999"},{"price":"0.21","size":"1999"},{"price":"0.2","size":"120"},{"price":"0.18","size":"15"},{"price":"0.16","size":"1999"},{"price":"0.15","size":"16.72"},{"price":"0.14","size":"10"},{"price":"0.11","size":"1999"},{"price":"0.09","size":"1999"},{"price":"0.08","size":"2610.27"},{"price":"0.07","size":"1600"},{"price":"0.06","size":"5"},{"price":"0.05","size":"2032.89"},{"price":"0.04","size":"2005"},{"price":"0.02","size":"1685.24"},{"price":"0.01","size":"761386.32"}],"min_order_size":"5","tick_size":"0.01","neg_risk":false,"last_trade_price":"0.990"}}
{"sample_number":19,"sample_utc":"2026-06-18T18:10:07.9147658+00:00","asset":"SOL","market_slug":"sol-updown-5m-1781805900","outcome":"Up","token_id":"17918595972159669296704757368041046382807284320771970511236606858231649587146","book":{"market":"0x6fe6c50e9739f3ec9f319c15d99b69bf1a986466f2ad035b006f6343b0fe7078","asset_id":"17918595972159669296704757368041046382807284320771970511236606858231649587146","timestamp":"1781806208194","hash":"ee6f906b2d5e62852eb20209edfb80addcf6db8f","bids":[{"price":"0.01","size":"110669"},{"price":"0.02","size":"1039"},{"price":"0.03","size":"27"},{"price":"0.04","size":"25020"},{"price":"0.05","size":"16"},{"price":"0.06","size":"8000"},{"price":"0.09","size":"999"},{"price":"0.1","size":"999"},{"price":"0.11","size":"2600"},{"price":"0.14","size":"2600"},{"price":"0.18","size":"999"},{"price":"0.19","size":"999"},{"price":"0.26","size":"999"},{"price":"0.27","size":"999"},{"price":"0.34","size":"999"},{"price":"0.35","size":"999"},{"price":"0.4","size":"12"},{"price":"0.42","size":"2600"},{"price":"0.43","size":"2600"},{"price":"0.55","size":"999"},{"price":"0.57","size":"999"},{"price":"0.65","size":"999"},{"price":"0.71","size":"2600"},{"price":"0.73","size":"2600"},{"price":"0.77","size":"999"},{"price":"0.79","size":"999"},{"price":"0.84","size":"999"},{"price":"0.86","size":"29.77"},{"price":"0.91","size":"1999"},{"price":"0.92","size":"1999"},{"price":"0.95","size":"2005"},{"price":"0.96","size":"2000"},{"price":"0.98","size":"58"},{"price":"0.99","size":"386473.2"}],"asks":[],"min_order_size":"5","tick_size":"0.01","neg_risk":false,"last_trade_price":"0.010"}}
{"sample_number":19,"sample_utc":"2026-06-18T18:10:07.9147658+00:00","asset":"SOL","market_slug":"sol-updown-5m-1781805900","outcome":"Down","token_id":"19093975118609871406874996908570798158581047681193006965676263914632124416327","book":{"market":"0x6fe6c50e9739f3ec9f319c15d99b69bf1a986466f2ad035b006f6343b0fe7078","asset_id":"19093975118609871406874996908570798158581047681193006965676263914632124416327","timestamp":"1781806208194","hash":"95ad29b46b8f69bfad7744721d133c4ab910036a","bids":[],"asks":[{"price":"0.99","size":"110669"},{"price":"0.98","size":"1039"},{"price":"0.97","size":"27"},{"price":"0.96","size":"25020"},{"price":"0.95","size":"16"},{"price":"0.94","size":"8000"},{"price":"0.91","size":"999"},{"price":"0.9","size":"999"},{"price":"0.89","size":"2600"},{"price":"0.86","size":"2600"},{"price":"0.82","size":"999"},{"price":"0.81","size":"999"},{"price":"0.74","size":"999"},{"price":"0.73","size":"999"},{"price":"0.66","size":"999"},{"price":"0.65","size":"999"},{"price":"0.6","size":"12"},{"price":"0.58","size":"2600"},{"price":"0.57","size":"2600"},{"price":"0.45","size":"999"},{"price":"0.43","size":"999"},{"price":"0.35","size":"999"},{"price":"0.29","size":"2600"},{"price":"0.27","size":"2600"},{"price":"0.23","size":"999"},{"price":"0.21","size":"999"},{"price":"0.16","size":"999"},{"price":"0.14","size":"29.77"},{"price":"0.09","size":"1999"},{"price":"0.08","size":"1999"},{"price":"0.05","size":"2005"},{"price":"0.04","size":"2000"},{"price":"0.02","size":"58"},{"price":"0.01","size":"386473.2"}],"min_order_size":"5","tick_size":"0.01","neg_risk":false,"last_trade_price":"0.010"}}
